<sdf version='1.6'>
  <model name='spot'>
    <link name='base_link'>
      <pose frame=''>0 0 0 0 -0 0</pose>
      <inertial>
        <pose frame=''>0.008465 0.004045 -0.000763 0 -0 0</pose>
        <mass>11.041</mass>
        <inertia>
          <ixx>0.050874</ixx>
          <ixy>-0.000451628</ixy>
          <ixz>0.000487603</ixz>
          <iyy>0.64036</iyy>
          <iyz>4.8356e-05</iyz>
          <izz>0.65655</izz>
        </inertia>
      </inertial>
      <collision name='base_link_collision'>
        <pose frame=''>0 0 0 0 -0 0</pose>
        <geometry>
          <mesh>
            <scale>1 1 1</scale>
            <uri>model://spot_description/meshes/body_collision.stl</uri>
          </mesh>
        </geometry>
      </collision>
      <visual name='base_link_visual'>
        <pose frame=''>0 0 0 0 -0 0</pose>
        <geometry>
          <mesh>
            <scale>1 1 1</scale>
            <uri>model://spot_description/meshes/body.dae</uri>
          </mesh>
        </geometry>
      </visual>
    </link>
    <link name='lf_hip'>
      <pose frame=''>0.29785 0.055 0 0 -0 0</pose>
      <inertial>
        <pose frame=''>-0.022191 0.015144 -1.5e-05 0 -0 0</pose>
        <mass>1.993</mass>
        <inertia>
          <ixx>0.00290389</ixx>
          <ixy>-7.185e-05</ixy>
          <ixz>-1.262e-06</ixz>
          <iyy>0.00490752</iyy>
          <iyz>-1.75e-06</iyz>
          <izz>0.00558694</izz>
        </inertia>
      </inertial>
      <collision name='lf_hip_collision'>
        <pose frame=''>0 0 0 0 -0 0</pose>
        <geometry>
          <mesh>
            <scale>1 1 1</scale>
            <uri>model://spot_description/meshes/front_left_hip_collision.stl</uri>
          </mesh>
        </geometry>
      </collision>
      <visual name='lf_hip_visual'>
        <pose frame=''>0 0 0 0 -0 0</pose>
        <geometry>
          <mesh>
            <scale>1 1 1</scale>
            <uri>model://spot_description/meshes/front_left_hip.dae</uri>
          </mesh>
        </geometry>
      </visual>
    </link>
    <joint name='lf_haa_joint' type='revolute'>
      <child>lf_hip</child>
      <parent>base_link</parent>
      <axis>
        <xyz>1 0 0</xyz>
        <limit>
          <lower>-0.785398</lower>
          <upper>0.785398</upper>
          <effort>50</effort>
          <velocity>1000</velocity>
        </limit>
        <dynamics>
          <spring_reference>0</spring_reference>
          <spring_stiffness>0</spring_stiffness>
        </dynamics>
        <use_parent_model_frame>0</use_parent_model_frame>
      </axis>
      <physics>
        <provide_feedback>1</provide_feedback>
        <ode>
          <provide_feedback>1</provide_feedback>
          <limit>
            <cfm>0</cfm>
            <erp>0.2</erp>
          </limit>
        </ode>
      </physics>
    </joint>
    <link name='lf_upperleg'>
      <pose frame=''>0.29785 0.165945 0 0 -0 0</pose>
      <inertial>
        <pose frame=''>-0.005607 -0.003877 -0.048199 0 -0 0</pose>
        <mass>0.639</mass>
        <inertia>
          <ixx>0.0056668</ixx>
          <ixy>3.597e-06</ixy>
          <ixz>0.000491446</ixz>
          <iyy>0.00584723</iyy>
          <iyz>1.0086e-05</iyz>
          <izz>0.000369811</izz>
        </inertia>
      </inertial>
      <collision name='lf_upperleg_collision'>
        <pose frame=''>0 0 0 0 -0 0</pose>
        <geometry>
          <mesh>
            <scale>1 1 1</scale>
            <uri>model://spot_description/meshes/front_left_upper_leg_collision.stl</uri>
          </mesh>
        </geometry>
        <surface>
          <contact>
            <ode>
              <kp>1e+06</kp>
              <kd>100</kd>
              <max_vel>1</max_vel>
              <min_depth>0</min_depth>
            </ode>
          </contact>
          <friction>
            <ode>
              <mu>1.5</mu>
              <mu2>1.5</mu2>
              <fdir1>1 0 0</fdir1>
            </ode>
          </friction>
        </surface>
      </collision>
      <visual name='lf_upperleg_visual'>
        <pose frame=''>0 0 0 0 -0 0</pose>
        <geometry>
          <mesh>
            <scale>1 1 1</scale>
            <uri>model://spot_description/meshes/front_left_upper_leg.dae</uri>
          </mesh>
        </geometry>
        <material>
          <script>
            <uri>__default__</uri>
            <name>__default__</name>
          </script>
        </material>
      </visual>
      <gravity>1</gravity>
      <velocity_decay/>
    </link>
    <joint name='lf_hfe_joint' type='revolute'>
      <child>lf_upperleg</child>
      <parent>lf_hip</parent>
      <axis>
        <xyz>0 1 0</xyz>
        <limit>
          <lower>-0.898845</lower>
          <upper>2.29511</upper>
          <effort>50</effort>
          <velocity>1000</velocity>
        </limit>
        <dynamics>
          <spring_reference>0</spring_reference>
          <spring_stiffness>0</spring_stiffness>
        </dynamics>
        <use_parent_model_frame>0</use_parent_model_frame>
      </axis>
      <physics>
        <provide_feedback>1</provide_feedback>
        <ode>
          <provide_feedback>1</provide_feedback>
          <limit>
            <cfm>0</cfm>
            <erp>0.2</erp>
          </limit>
        </ode>
      </physics>
    </joint>
    <link name='lf_lowerleg'>
      <pose frame=''>0.32285 0.165945 -0.3205 0 -0 0</pose>
      <inertial>
        <pose frame=''>0.001032 4.9e-05 -0.188694 0 -0 0</pose>
        <mass>0.267</mass>
        <inertia>
          <ixx>0.00832704</ixx>
          <ixy>-2.58027e-08</ixy>
          <ixz>-0.000162325</ixz>
          <iyy>0.00834365</iyy>
          <iyz>-1.93818e-06</iyz>
          <izz>6.36045e-05</izz>
        </inertia>
      </inertial>
      <collision name='lf_lowerleg_collision'>
        <pose frame=''>0 0 0 0 -0 0</pose>
        <geometry>
          <mesh>
            <scale>1 1 1</scale>
            <uri>model://spot_description/meshes/front_left_lower_leg_collision.stl</uri>
          </mesh>
        </geometry>
        <surface>
          <contact>
            <ode>
              <kp>1e+06</kp>
              <kd>100</kd>
              <max_vel>1</max_vel>
            </ode>
          </contact>
          <friction>
            <ode>
              <mu>1</mu>
              <mu2>1</mu2>
            </ode>
          </friction>
        </surface>
        <max_contacts>1</max_contacts>
      </collision>
      <collision name='lf_lowerleg_fixed_joint_lump__lf_foot_collision_1'>
        <pose frame=''>-0.005 0 -0.348 0 -0 0</pose>
        <geometry>
          <sphere>
            <radius>0.03</radius>
          </sphere>
        </geometry>
        <surface>
          <contact>
            <ode>
              <kp>1e+06</kp>
              <kd>100</kd>
              <max_vel>1</max_vel>
            </ode>
          </contact>
          <friction>
            <ode>
              <mu>1</mu>
              <mu2>1</mu2>
            </ode>
          </friction>
        </surface>
        <max_contacts>1</max_contacts>
      </collision>
      <visual name='lf_lowerleg_visual'>
        <pose frame=''>0 0 0 0 -0 0</pose>
        <geometry>
          <mesh>
            <scale>1 1 1</scale>
            <uri>model://spot_description/meshes/front_left_lower_leg.dae</uri>
          </mesh>
        </geometry>
        <material>
          <script>
            <uri>__default__</uri>
            <name>__default__</name>
          </script>
        </material>
      </visual>
      <visual name='lf_lowerleg_fixed_joint_lump__lf_foot_visual_1'>
        <pose frame=''>-0.005 0 -0.348 0 -0 0</pose>
        <geometry>
          <sphere>
            <radius>0.02</radius>
          </sphere>
        </geometry>
        <material>
          <script>
            <name>Gazebo/Black</name>
            <uri>file://media/materials/scripts/gazebo.material</uri>
          </script>
        </material>
      </visual>
      <velocity_decay/>
      <sensor name='lf_shin_contact_sensor' type='contact'>
        <always_on>1</always_on>
        <update_rate>250</update_rate>
        <contact>
          <collision>lf_lowerleg_collision</collision>
          <topic>__default_topic__</topic>
        </contact>
      </sensor>
      <gravity>1</gravity>
      <velocity_decay/>
      <sensor name='lf_foot_contact_sensor' type='contact'>
        <always_on>1</always_on>
        <update_rate>250</update_rate>
        <contact>
          <collision>lf_lowerleg_fixed_joint_lump__lf_foot_collision_1</collision>
          <topic>__default_topic__</topic>
        </contact>
        <pose frame=''>-0.005 0 -0.348 0 -0 0</pose>
      </sensor>
    </link>
    <joint name='lf_kfe_joint' type='revolute'>
      <child>lf_lowerleg</child>
      <parent>lf_upperleg</parent>
      <axis>
        <xyz>0 1 0</xyz>
        <limit>
          <lower>-2.7929</lower>
          <upper>-0.254801</upper>
          <effort>50</effort>
          <velocity>1000</velocity>
        </limit>
        <dynamics>
          <spring_reference>0</spring_reference>
          <spring_stiffness>0</spring_stiffness>
        </dynamics>
        <use_parent_model_frame>0</use_parent_model_frame>
      </axis>
      <physics>
        <provide_feedback>1</provide_feedback>
        <ode>
          <provide_feedback>1</provide_feedback>
          <limit>
            <cfm>0</cfm>
            <erp>0.2</erp>
          </limit>
        </ode>
      </physics>
    </joint>
    <link name='lh_hip'>
      <pose frame=''>-0.29785 0.055 0 0 -0 0</pose>
      <inertial>
        <pose frame=''>0.022191 0.015144 -1.5e-05 0 -0 0</pose>
        <mass>1.993</mass>
        <inertia>
          <ixx>0.00290389</ixx>
          <ixy>7.185e-05</ixy>
          <ixz>1.262e-06</ixz>
          <iyy>0.00490752</iyy>
          <iyz>-1.75e-06</iyz>
          <izz>0.00558694</izz>
        </inertia>
      </inertial>
      <collision name='lh_hip_collision'>
        <pose frame=''>0 0 0 0 -0 0</pose>
        <geometry>
          <mesh>
            <scale>1 1 1</scale>
            <uri>model://spot_description/meshes/rear_left_hip_collision.stl</uri>
          </mesh>
        </geometry>
      </collision>
      <visual name='lh_hip_visual'>
        <pose frame=''>0 0 0 0 -0 0</pose>
        <geometry>
          <mesh>
            <scale>1 1 1</scale>
            <uri>model://spot_description/meshes/rear_left_hip.dae</uri>
          </mesh>
        </geometry>
      </visual>
    </link>
    <joint name='lh_haa_joint' type='revolute'>
      <child>lh_hip</child>
      <parent>base_link</parent>
      <axis>
        <xyz>1 0 0</xyz>
        <limit>
          <lower>-0.785398</lower>
          <upper>0.785398</upper>
          <effort>50</effort>
          <velocity>1000</velocity>
        </limit>
        <dynamics>
          <spring_reference>0</spring_reference>
          <spring_stiffness>0</spring_stiffness>
        </dynamics>
        <use_parent_model_frame>0</use_parent_model_frame>
      </axis>
      <physics>
        <provide_feedback>1</provide_feedback>
        <ode>
          <provide_feedback>1</provide_feedback>
          <limit>
            <cfm>0</cfm>
            <erp>0.2</erp>
          </limit>
        </ode>
      </physics>
    </joint>
    <link name='lh_upperleg'>
      <pose frame=''>-0.29785 0.165945 0 0 -0 0</pose>
      <inertial>
        <pose frame=''>-0.005607 -0.003877 -0.048199 0 -0 0</pose>
        <mass>0.639</mass>
        <inertia>
          <ixx>0.0056668</ixx>
          <ixy>3.597e-06</ixy>
          <ixz>0.000491446</ixz>
          <iyy>0.00584723</iyy>
          <iyz>1.0086e-05</iyz>
          <izz>0.000369811</izz>
        </inertia>
      </inertial>
      <collision name='lh_upperleg_collision'>
        <pose frame=''>0 0 0 0 -0 0</pose>
        <geometry>
          <mesh>
            <scale>1 1 1</scale>
            <uri>model://spot_description/meshes/rear_left_upper_leg_collision.stl</uri>
          </mesh>
        </geometry>
        <surface>
          <contact>
            <ode>
              <kp>1e+06</kp>
              <kd>100</kd>
              <max_vel>1</max_vel>
              <min_depth>0</min_depth>
            </ode>
          </contact>
          <friction>
            <ode>
              <mu>1.5</mu>
              <mu2>1.5</mu2>
              <fdir1>1 0 0</fdir1>
            </ode>
          </friction>
        </surface>
      </collision>
      <visual name='lh_upperleg_visual'>
        <pose frame=''>0 0 0 0 -0 0</pose>
        <geometry>
          <mesh>
            <scale>1 1 1</scale>
            <uri>model://spot_description/meshes/rear_left_upper_leg.dae</uri>
          </mesh>
        </geometry>
        <material>
          <script>
            <uri>__default__</uri>
            <name>__default__</name>
          </script>
        </material>
      </visual>
      <gravity>1</gravity>
      <velocity_decay/>
    </link>
    <joint name='lh_hfe_joint' type='revolute'>
      <child>lh_upperleg</child>
      <parent>lh_hip</parent>
      <axis>
        <xyz>0 1 0</xyz>
        <limit>
          <lower>-0.898845</lower>
          <upper>2.29511</upper>
          <effort>50</effort>
          <velocity>1000</velocity>
        </limit>
        <dynamics>
          <spring_reference>0</spring_reference>
          <spring_stiffness>0</spring_stiffness>
        </dynamics>
        <use_parent_model_frame>0</use_parent_model_frame>
      </axis>
      <physics>
        <provide_feedback>1</provide_feedback>
        <ode>
          <provide_feedback>1</provide_feedback>
          <limit>
            <cfm>0</cfm>
            <erp>0.2</erp>
          </limit>
        </ode>
      </physics>
    </joint>
    <link name='lh_lowerleg'>
      <pose frame=''>-0.27285 0.165945 -0.3205 0 -0 0</pose>
      <inertial>
        <pose frame=''>0.001032 4.9e-05 -0.188694 0 -0 0</pose>
        <mass>0.267</mass>
        <inertia>
          <ixx>0.00832704</ixx>
          <ixy>-2.58027e-08</ixy>
          <ixz>-0.000162325</ixz>
          <iyy>0.00834365</iyy>
          <iyz>-1.93818e-06</iyz>
          <izz>6.36045e-05</izz>
        </inertia>
      </inertial>
      <collision name='lh_lowerleg_collision'>
        <pose frame=''>0 0 0 0 -0 0</pose>
        <geometry>
          <mesh>
            <scale>1 1 1</scale>
            <uri>model://spot_description/meshes/rear_left_lower_leg_collision.stl</uri>
          </mesh>
        </geometry>
        <surface>
          <contact>
            <ode>
              <kp>1e+06</kp>
              <kd>100</kd>
              <max_vel>1</max_vel>
            </ode>
          </contact>
          <friction>
            <ode>
              <mu>1</mu>
              <mu2>1</mu2>
            </ode>
          </friction>
        </surface>
        <max_contacts>1</max_contacts>
      </collision>
      <collision name='lh_lowerleg_fixed_joint_lump__lh_foot_collision_1'>
        <pose frame=''>-0.005 0 -0.348 0 -0 0</pose>
        <geometry>
          <sphere>
            <radius>0.03</radius>
          </sphere>
        </geometry>
        <surface>
          <contact>
            <ode>
              <kp>1e+06</kp>
              <kd>100</kd>
              <max_vel>1</max_vel>
            </ode>
          </contact>
          <friction>
            <ode>
              <mu>1</mu>
              <mu2>1</mu2>
            </ode>
          </friction>
        </surface>
        <max_contacts>1</max_contacts>
      </collision>
      <visual name='lh_lowerleg_visual'>
        <pose frame=''>0 0 0 0 -0 0</pose>
        <geometry>
          <mesh>
            <scale>1 1 1</scale>
            <uri>model://spot_description/meshes/rear_left_lower_leg.dae</uri>
          </mesh>
        </geometry>
        <material>
          <script>
            <uri>__default__</uri>
            <name>__default__</name>
          </script>
        </material>
      </visual>
      <visual name='lh_lowerleg_fixed_joint_lump__lh_foot_visual_1'>
        <pose frame=''>-0.005 0 -0.348 0 -0 0</pose>
        <geometry>
          <sphere>
            <radius>0.02</radius>
          </sphere>
        </geometry>
        <material>
          <script>
            <name>Gazebo/Black</name>
            <uri>file://media/materials/scripts/gazebo.material</uri>
          </script>
        </material>
      </visual>
      <velocity_decay/>
      <sensor name='lh_shin_contact_sensor' type='contact'>
        <always_on>1</always_on>
        <update_rate>250</update_rate>
        <contact>
          <collision>lh_lowerleg_collision</collision>
          <topic>__default_topic__</topic>
        </contact>
      </sensor>
      <gravity>1</gravity>
      <velocity_decay/>
      <sensor name='lh_foot_contact_sensor' type='contact'>
        <always_on>1</always_on>
        <update_rate>250</update_rate>
        <contact>
          <collision>lh_lowerleg_fixed_joint_lump__lh_foot_collision_1</collision>
          <topic>__default_topic__</topic>
        </contact>
        <pose frame=''>-0.005 0 -0.348 0 -0 0</pose>
      </sensor>
    </link>
    <joint name='lh_kfe_joint' type='revolute'>
      <child>lh_lowerleg</child>
      <parent>lh_upperleg</parent>
      <axis>
        <xyz>0 1 0</xyz>
        <limit>
          <lower>-2.7929</lower>
          <upper>-0.267153</upper>
          <effort>50</effort>
          <velocity>1000</velocity>
        </limit>
        <dynamics>
          <spring_reference>0</spring_reference>
          <spring_stiffness>0</spring_stiffness>
        </dynamics>
        <use_parent_model_frame>0</use_parent_model_frame>
      </axis>
      <physics>
        <provide_feedback>1</provide_feedback>
        <ode>
          <provide_feedback>1</provide_feedback>
          <limit>
            <cfm>0</cfm>
            <erp>0.2</erp>
          </limit>
        </ode>
      </physics>
    </joint>
    <link name='rf_hip'>
      <pose frame=''>0.29785 -0.055 0 0 -0 0</pose>
      <inertial>
        <pose frame=''>-0.022191 -0.015144 -1.5e-05 0 -0 0</pose>
        <mass>1.993</mass>
        <inertia>
          <ixx>0.00290389</ixx>
          <ixy>7.185e-05</ixy>
          <ixz>-1.262e-06</ixz>
          <iyy>0.00490752</iyy>
          <iyz>1.75e-06</iyz>
          <izz>0.00558694</izz>
        </inertia>
      </inertial>
      <collision name='rf_hip_collision'>
        <pose frame=''>0 0 0 0 -0 0</pose>
        <geometry>
          <mesh>
            <scale>1 1 1</scale>
            <uri>model://spot_description/meshes/front_right_hip_collision.stl</uri>
          </mesh>
        </geometry>
      </collision>
      <visual name='rf_hip_visual'>
        <pose frame=''>0 0 0 0 -0 0</pose>
        <geometry>
          <mesh>
            <scale>1 1 1</scale>
            <uri>model://spot_description/meshes/front_right_hip.dae</uri>
          </mesh>
        </geometry>
      </visual>
    </link>
    <joint name='rf_haa_joint' type='revolute'>
      <child>rf_hip</child>
      <parent>base_link</parent>
      <axis>
        <xyz>1 0 0</xyz>
        <limit>
          <lower>-0.785398</lower>
          <upper>0.785398</upper>
          <effort>50</effort>
          <velocity>1000</velocity>
        </limit>
        <dynamics>
          <spring_reference>0</spring_reference>
          <spring_stiffness>0</spring_stiffness>
        </dynamics>
        <use_parent_model_frame>0</use_parent_model_frame>
      </axis>
      <physics>
        <provide_feedback>1</provide_feedback>
        <ode>
          <provide_feedback>1</provide_feedback>
          <limit>
            <cfm>0</cfm>
            <erp>0.2</erp>
          </limit>
        </ode>
      </physics>
    </joint>
    <link name='rf_upperleg'>
      <pose frame=''>0.29785 -0.165945 0 0 -0 0</pose>
      <inertial>
        <pose frame=''>-0.005607 0.003877 -0.048199 0 -0 0</pose>
        <mass>0.639</mass>
        <inertia>
          <ixx>0.0056668</ixx>
          <ixy>-3.597e-06</ixy>
          <ixz>0.000491446</ixz>
          <iyy>0.00584723</iyy>
          <iyz>-1.0086e-05</iyz>
          <izz>0.000369811</izz>
        </inertia>
      </inertial>
      <collision name='rf_upperleg_collision'>
        <pose frame=''>0 0 0 0 -0 0</pose>
        <geometry>
          <mesh>
            <scale>1 1 1</scale>
            <uri>model://spot_description/meshes/front_right_upper_leg_collision.stl</uri>
          </mesh>
        </geometry>
        <surface>
          <contact>
            <ode>
              <kp>1e+06</kp>
              <kd>100</kd>
              <max_vel>1</max_vel>
              <min_depth>0</min_depth>
            </ode>
          </contact>
          <friction>
            <ode>
              <mu>1.5</mu>
              <mu2>1.5</mu2>
              <fdir1>1 0 0</fdir1>
            </ode>
          </friction>
        </surface>
      </collision>
      <visual name='rf_upperleg_visual'>
        <pose frame=''>0 0 0 0 -0 0</pose>
        <geometry>
          <mesh>
            <scale>1 1 1</scale>
            <uri>model://spot_description/meshes/front_right_upper_leg.dae</uri>
          </mesh>
        </geometry>
        <material>
          <script>
            <uri>__default__</uri>
            <name>__default__</name>
          </script>
        </material>
      </visual>
      <gravity>1</gravity>
      <velocity_decay/>
    </link>
    <joint name='rf_hfe_joint' type='revolute'>
      <child>rf_upperleg</child>
      <parent>rf_hip</parent>
      <axis>
        <xyz>0 1 0</xyz>
        <limit>
          <lower>-0.898845</lower>
          <upper>2.29511</upper>
          <effort>50</effort>
          <velocity>1000</velocity>
        </limit>
        <dynamics>
          <spring_reference>0</spring_reference>
          <spring_stiffness>0</spring_stiffness>
        </dynamics>
        <use_parent_model_frame>0</use_parent_model_frame>
      </axis>
      <physics>
        <provide_feedback>1</provide_feedback>
        <ode>
          <provide_feedback>1</provide_feedback>
          <limit>
            <cfm>0</cfm>
            <erp>0.2</erp>
          </limit>
        </ode>
      </physics>
    </joint>
    <link name='rf_lowerleg'>
      <pose frame=''>0.32285 -0.165945 -0.3205 0 -0 0</pose>
      <inertial>
        <pose frame=''>0.001032 -4.9e-05 -0.188694 0 -0 0</pose>
        <mass>0.267</mass>
        <inertia>
          <ixx>0.00832704</ixx>
          <ixy>2.58027e-08</ixy>
          <ixz>-0.000162325</ixz>
          <iyy>0.00834365</iyy>
          <iyz>1.93818e-06</iyz>
          <izz>6.36045e-05</izz>
        </inertia>
      </inertial>
      <collision name='rf_lowerleg_collision'>
        <pose frame=''>0 0 0 0 -0 0</pose>
        <geometry>
          <mesh>
            <scale>1 1 1</scale>
            <uri>model://spot_description/meshes/front_right_lower_leg_collision.stl</uri>
          </mesh>
        </geometry>
        <surface>
          <contact>
            <ode>
              <kp>1e+06</kp>
              <kd>100</kd>
              <max_vel>1</max_vel>
            </ode>
          </contact>
          <friction>
            <ode>
              <mu>1</mu>
              <mu2>1</mu2>
            </ode>
          </friction>
        </surface>
        <max_contacts>1</max_contacts>
      </collision>
      <collision name='rf_lowerleg_fixed_joint_lump__rf_foot_collision_1'>
        <pose frame=''>-0.005 0 -0.348 0 -0 0</pose>
        <geometry>
          <sphere>
            <radius>0.03</radius>
          </sphere>
        </geometry>
        <surface>
          <contact>
            <ode>
              <kp>1e+06</kp>
              <kd>100</kd>
              <max_vel>1</max_vel>
            </ode>
          </contact>
          <friction>
            <ode>
              <mu>1</mu>
              <mu2>1</mu2>
            </ode>
          </friction>
        </surface>
        <max_contacts>1</max_contacts>
      </collision>
      <visual name='rf_lowerleg_visual'>
        <pose frame=''>0 0 0 0 -0 0</pose>
        <geometry>
          <mesh>
            <scale>1 1 1</scale>
            <uri>model://spot_description/meshes/front_right_lower_leg.dae</uri>
          </mesh>
        </geometry>
        <material>
          <script>
            <uri>__default__</uri>
            <name>__default__</name>
          </script>
        </material>
      </visual>
      <visual name='rf_lowerleg_fixed_joint_lump__rf_foot_visual_1'>
        <pose frame=''>-0.005 0 -0.348 0 -0 0</pose>
        <geometry>
          <sphere>
            <radius>0.02</radius>
          </sphere>
        </geometry>
        <material>
          <script>
            <name>Gazebo/Black</name>
            <uri>file://media/materials/scripts/gazebo.material</uri>
          </script>
        </material>
      </visual>
      <velocity_decay/>
      <sensor name='rf_shin_contact_sensor' type='contact'>
        <always_on>1</always_on>
        <update_rate>250</update_rate>
        <contact>
          <collision>rf_lowerleg_collision</collision>
          <topic>__default_topic__</topic>
        </contact>
      </sensor>
      <gravity>1</gravity>
      <velocity_decay/>
      <sensor name='rf_foot_contact_sensor' type='contact'>
        <always_on>1</always_on>
        <update_rate>250</update_rate>
        <contact>
          <collision>rf_lowerleg_fixed_joint_lump__rf_foot_collision_1</collision>
          <topic>__default_topic__</topic>
        </contact>
        <pose frame=''>-0.005 0 -0.348 0 -0 0</pose>
      </sensor>
    </link>
    <joint name='rf_kfe_joint' type='revolute'>
      <child>rf_lowerleg</child>
      <parent>rf_upperleg</parent>
      <axis>
        <xyz>0 1 0</xyz>
        <limit>
          <lower>-2.7929</lower>
          <upper>-0.247563</upper>
          <effort>50</effort>
          <velocity>1000</velocity>
        </limit>
        <dynamics>
          <spring_reference>0</spring_reference>
          <spring_stiffness>0</spring_stiffness>
        </dynamics>
        <use_parent_model_frame>0</use_parent_model_frame>
      </axis>
      <physics>
        <provide_feedback>1</provide_feedback>
        <ode>
          <provide_feedback>1</provide_feedback>
          <limit>
            <cfm>0</cfm>
            <erp>0.2</erp>
          </limit>
        </ode>
      </physics>
    </joint>
    <link name='rh_hip'>
      <pose frame=''>-0.29785 -0.055 0 0 -0 0</pose>
      <inertial>
        <pose frame=''>0.022191 -0.015144 -1.5e-05 0 -0 0</pose>
        <mass>1.993</mass>
        <inertia>
          <ixx>0.00290389</ixx>
          <ixy>-7.185e-05</ixy>
          <ixz>1.262e-06</ixz>
          <iyy>0.00490752</iyy>
          <iyz>1.75e-06</iyz>
          <izz>0.00558694</izz>
        </inertia>
      </inertial>
      <collision name='rh_hip_collision'>
        <pose frame=''>0 0 0 0 -0 0</pose>
        <geometry>
          <mesh>
            <scale>1 1 1</scale>
            <uri>model://spot_description/meshes/rear_right_hip_collision.stl</uri>
          </mesh>
        </geometry>
      </collision>
      <visual name='rh_hip_visual'>
        <pose frame=''>0 0 0 0 -0 0</pose>
        <geometry>
          <mesh>
            <scale>1 1 1</scale>
            <uri>model://spot_description/meshes/rear_right_hip.dae</uri>
          </mesh>
        </geometry>
      </visual>
    </link>
    <joint name='rh_haa_joint' type='revolute'>
      <child>rh_hip</child>
      <parent>base_link</parent>
      <axis>
        <xyz>1 0 0</xyz>
        <limit>
          <lower>-0.785398</lower>
          <upper>0.785398</upper>
          <effort>50</effort>
          <velocity>1000</velocity>
        </limit>
        <dynamics>
          <spring_reference>0</spring_reference>
          <spring_stiffness>0</spring_stiffness>
        </dynamics>
        <use_parent_model_frame>0</use_parent_model_frame>
      </axis>
      <physics>
        <provide_feedback>1</provide_feedback>
        <ode>
          <provide_feedback>1</provide_feedback>
          <limit>
            <cfm>0</cfm>
            <erp>0.2</erp>
          </limit>
        </ode>
      </physics>
    </joint>
    <link name='rh_upperleg'>
      <pose frame=''>-0.29785 -0.165945 0 0 -0 0</pose>
      <inertial>
        <pose frame=''>-0.005607 0.003877 -0.048199 0 -0 0</pose>
        <mass>0.639</mass>
        <inertia>
          <ixx>0.0056668</ixx>
          <ixy>-3.597e-06</ixy>
          <ixz>0.000491446</ixz>
          <iyy>0.00584723</iyy>
          <iyz>-1.0086e-05</iyz>
          <izz>0.000369811</izz>
        </inertia>
      </inertial>
      <collision name='rh_upperleg_collision'>
        <pose frame=''>0 0 0 0 -0 0</pose>
        <geometry>
          <mesh>
            <scale>1 1 1</scale>
            <uri>model://spot_description/meshes/rear_right_upper_leg_collision.stl</uri>
          </mesh>
        </geometry>
        <surface>
          <contact>
            <ode>
              <kp>1e+06</kp>
              <kd>100</kd>
              <max_vel>1</max_vel>
              <min_depth>0</min_depth>
            </ode>
          </contact>
          <friction>
            <ode>
              <mu>1.5</mu>
              <mu2>1.5</mu2>
              <fdir1>1 0 0</fdir1>
            </ode>
          </friction>
        </surface>
      </collision>
      <visual name='rh_upperleg_visual'>
        <pose frame=''>0 0 0 0 -0 0</pose>
        <geometry>
          <mesh>
            <scale>1 1 1</scale>
            <uri>model://spot_description/meshes/rear_right_upper_leg.dae</uri>
          </mesh>
        </geometry>
        <material>
          <script>
            <uri>__default__</uri>
            <name>__default__</name>
          </script>
        </material>
      </visual>
      <gravity>1</gravity>
      <velocity_decay/>
    </link>
    <joint name='rh_hfe_joint' type='revolute'>
      <child>rh_upperleg</child>
      <parent>rh_hip</parent>
      <axis>
        <xyz>0 1 0</xyz>
        <limit>
          <lower>-0.898845</lower>
          <upper>2.29511</upper>
          <effort>50</effort>
          <velocity>1000</velocity>
        </limit>
        <dynamics>
          <spring_reference>0</spring_reference>
          <spring_stiffness>0</spring_stiffness>
        </dynamics>
        <use_parent_model_frame>0</use_parent_model_frame>
      </axis>
      <physics>
        <provide_feedback>1</provide_feedback>
        <ode>
          <provide_feedback>1</provide_feedback>
          <limit>
            <cfm>0</cfm>
            <erp>0.2</erp>
          </limit>
        </ode>
      </physics>
    </joint>
    <link name='rh_lowerleg'>
      <pose frame=''>-0.27285 -0.165945 -0.3205 0 -0 0</pose>
      <inertial>
        <pose frame=''>0.001032 -4.9e-05 -0.188694 0 -0 0</pose>
        <mass>0.267</mass>
        <inertia>
          <ixx>0.00832704</ixx>
          <ixy>2.58027e-08</ixy>
          <ixz>-0.000162325</ixz>
          <iyy>0.00834365</iyy>
          <iyz>1.93818e-06</iyz>
          <izz>6.36045e-05</izz>
        </inertia>
      </inertial>
      <collision name='rh_lowerleg_collision'>
        <pose frame=''>0 0 0 0 -0 0</pose>
        <geometry>
          <mesh>
            <scale>1 1 1</scale>
            <uri>model://spot_description/meshes/rear_right_lower_leg_collision.stl</uri>
          </mesh>
        </geometry>
        <surface>
          <contact>
            <ode>
              <kp>1e+06</kp>
              <kd>100</kd>
              <max_vel>1</max_vel>
            </ode>
          </contact>
          <friction>
            <ode>
              <mu>1</mu>
              <mu2>1</mu2>
            </ode>
          </friction>
        </surface>
        <max_contacts>1</max_contacts>
      </collision>
      <collision name='rh_lowerleg_fixed_joint_lump__rh_foot_collision_1'>
        <pose frame=''>-0.005 0 -0.348 0 -0 0</pose>
        <geometry>
          <sphere>
            <radius>0.03</radius>
          </sphere>
        </geometry>
        <surface>
          <contact>
            <ode>
              <kp>1e+06</kp>
              <kd>100</kd>
              <max_vel>1</max_vel>
            </ode>
          </contact>
          <friction>
            <ode>
              <mu>1</mu>
              <mu2>1</mu2>
            </ode>
          </friction>
        </surface>
        <max_contacts>1</max_contacts>
      </collision>
      <visual name='rh_lowerleg_visual'>
        <pose frame=''>0 0 0 0 -0 0</pose>
        <geometry>
          <mesh>
            <scale>1 1 1</scale>
            <uri>model://spot_description/meshes/rear_right_lower_leg.dae</uri>
          </mesh>
        </geometry>
        <material>
          <script>
            <uri>__default__</uri>
            <name>__default__</name>
          </script>
        </material>
      </visual>
      <visual name='rh_lowerleg_fixed_joint_lump__rh_foot_visual_1'>
        <pose frame=''>-0.005 0 -0.348 0 -0 0</pose>
        <geometry>
          <sphere>
            <radius>0.02</radius>
          </sphere>
        </geometry>
        <material>
          <script>
            <name>Gazebo/Black</name>
            <uri>file://media/materials/scripts/gazebo.material</uri>
          </script>
        </material>
      </visual>
      <velocity_decay/>
      <sensor name='rh_shin_contact_sensor' type='contact'>
        <always_on>1</always_on>
        <update_rate>250</update_rate>
        <contact>
          <collision>rh_lowerleg_collision</collision>
          <topic>__default_topic__</topic>
        </contact>
      </sensor>
      <gravity>1</gravity>
      <velocity_decay/>
      <sensor name='rh_foot_contact_sensor' type='contact'>
        <always_on>1</always_on>
        <update_rate>250</update_rate>
        <contact>
          <collision>rh_lowerleg_fixed_joint_lump__rh_foot_collision_1</collision>
          <topic>__default_topic__</topic>
        </contact>
        <pose frame=''>-0.005 0 -0.348 0 -0 0</pose>
      </sensor>
    </link>
    <joint name='rh_kfe_joint' type='revolute'>
      <child>rh_lowerleg</child>
      <parent>rh_upperleg</parent>
      <axis>
        <xyz>0 1 0</xyz>
        <limit>
          <lower>-2.7929</lower>
          <upper>-0.257725</upper>
          <effort>50</effort>
          <velocity>1000</velocity>
        </limit>
        <dynamics>
          <spring_reference>0</spring_reference>
          <spring_stiffness>0</spring_stiffness>
        </dynamics>
        <use_parent_model_frame>0</use_parent_model_frame>
      </axis>
      <physics>
        <provide_feedback>1</provide_feedback>
        <ode>
          <provide_feedback>1</provide_feedback>
          <limit>
            <cfm>0</cfm>
            <erp>0.2</erp>
          </limit>
        </ode>
      </physics>
    </joint>
    <static>0</static>
  </model>
</sdf>
