<?xml version="1.0" encoding="utf-8"?>
<!-- =================================================================================== -->
<!--   Copyright 2019 ANYbotics, https://www.anybotics.com                               -->
<!-- =================================================================================== -->
<!-- This file contains the description of the ANYmal B robot. -->
<robot name="anymal" xmlns:xacro="http://www.ros.org/wiki/xacro">

    <!-- This argument allows us to load joint sensors that measure the internal wrenches -->
    <xacro:arg name="load_force_sensors" default="false"/>
    <xacro:arg name="task_period" default="0.004"/>
    <xacro:arg name="floating_base_link" default="true"/>
    <xacro:arg name="robot_name"  default="anymal"/>
    <xacro:arg name="base_name"   default="base_link"/>

    <!-- load generic materials -->
    <xacro:include filename="$(find wolf_description_utils)/urdfs/materials.xacro"/>

    <!-- generic simulator_gazebo plugins for starting mechanism control, ros time -->
    <xacro:include filename="$(find wolf_description_utils)/urdfs/gazebo.urdf.xacro"/>

    <!-- legs transmission and gazebo plugins -->
    <xacro:include filename="$(find wolf_description_utils)/urdfs/leg.transmission.xacro"/>
    <xacro:include filename="$(find wolf_description_utils)/urdfs/leg.gazebo.xacro"/>

    <!-- Material for the visual primitives -->  
    <material name="anymal_material">    
        <color rgba="0.7 0.7 0.7 1.0"/>  
    </material>  

    <!-- Base link -->  
    <link name="base_link">
        <visual>      
            <origin rpy="0 0 0" xyz="0 0 0"/>      
            <geometry>        
                <mesh filename="package://anymal_description/meshes/anymal_base.dae" scale="0.001 0.001     0.001"/>
            </geometry>      
            <material name="anymal_material"/>    
        </visual>    
        <collision>      
            <!-- Main Body -->      
            <origin rpy="0 0 0" xyz="0 0 0.08"/>      
            <geometry>        
                <box size="0.531 0.27 0.24"/>      
            </geometry>    
        </collision>    
        <collision>      
            <!-- HAA actuators -->      
            <origin rpy="0 1.57079632679 0" xyz="0.227 0.116 0"/>      
            <geometry>        
                <cylinder length="0.1" radius="0.05"/>      
            </geometry>    
        </collision>    
        <collision>      
            <origin rpy="0 1.57079632679 0" xyz="0.227 -0.116 0"/>      
            <geometry>        
                <cylinder length="0.1" radius="0.05"/>      
            </geometry>    
        </collision>    
        <collision>      
            <origin rpy="0 1.57079632679 0" xyz="-0.227 0.116 0"/>      
            <geometry>        
                <cylinder length="0.1" radius="0.05"/>      
            </geometry>    
        </collision>    
        <collision>      
            <origin rpy="0 1.57079632679 0" xyz="-0.227 -0.116 0"/>      
            <geometry>        
                <cylinder length="0.1" radius="0.05"/>      
            </geometry>    
        </collision>    
        <collision>      
            <!-- Belly plate front bump -->      
            <origin rpy="0 0 0" xyz="0.2155 0.0 -0.09"/>      
            <geometry>        
                <box size="0.1 0.1 0.07"/>      
            </geometry>    
        </collision>    
        <collision>      
            <!-- Belly plate hind bump-->      
            <origin rpy="0 0 0" xyz="-0.2155 0.0 -0.09"/>      
            <geometry>        
                <box size="0.1 0.1 0.07"/>      
            </geometry>    
        </collision>    
        <collision>      
            <!-- Belly plate middle bump-->      
            <origin rpy="0 0 0" xyz="0 0 -0.09"/>      
            <geometry>        
                <box size="0.531 0.02 0.07"/>      
            </geometry>    
        </collision>  
    </link>

    <!-- Floating-base Joint -->
    <xacro:if value="$(arg floating_base_link)">
	    <link name="world"/>
	    <joint name="floating_base_joint" type="floating">
	      <origin rpy="0 0 0" xyz="0 0 0"/>
	      <parent link="world"/>
	      <child link="base_link"/>
	    </joint>
    </xacro:if>
    <joint name="floating_base" type="fixed">
      <origin rpy="0 0 0" xyz="0 0 0"/>
      <parent link="base_link"/>
      <child link="trunk"/>
    </joint>
    <link name="trunk"/>

    <!-- Fixed joint to add dummy inertia link -->  
    <joint name="base_to_base_inertia" type="fixed">    
        <parent link="trunk"/>
        <child link="base_inertia"/>    
        <origin rpy="0 0 0" xyz="0 0 0"/>  
    </joint>  
    <!-- Dummy inertia link, because KDL cannot have inertia on the base link -->  
    <link name="base_inertia">    
        <inertial>      
            <origin rpy="0 0 0" xyz="-0.001960558279 -0.001413217745 0.050207125344"/>      
            <mass value="40.793507758"/>      
            <inertia ixx="0.217391101503" ixy="-0.00132873239126" ixz="-0.00228200226173" iyy="0.639432546734" iyz="-0.00138078263145" izz="0.62414077654"/>    
        </inertial>  
    </link>  
    <link name="lf_hip">
        <visual>      
            <origin rpy="0 0 0.0" xyz="0 0 0"/>      
            <geometry>        
                <mesh filename="package://anymal_description/meshes/anymal_hip_l.dae" scale="0.001 0.001     0.001"/>
            </geometry>      
            <material name="anymal_material"/>    
        </visual>    
        <collision>      
            <!-- Protector -->      
            <origin rpy="1.57079632679 0 0" xyz="0.0635 -0.009 0.0"/>      
            <geometry>        
                <cylinder length="0.1" radius="0.08"/>      
            </geometry>    
        </collision>    
        <collision>      
            <!-- Heatfins -->      
            <origin rpy="1.57079632679 0 0" xyz="0.0635 -0.074 0.0"/>      
            <geometry>        
                <cylinder length="0.03" radius="0.045"/>      
            </geometry>    
        </collision>    
        <inertial>      
            <origin rpy="0 0 0" xyz="0.064516258147 -0.003787101702 -0.000152184388"/>      
            <mass value="1.42462064"/>      
            <inertia ixx="0.00243023349564" ixy="-1.53023971e-05" ixz="-2.1819095354e-05" iyy="0.00230257239103" iyz="2.6473021273e-05" izz="0.0019806759227"/>    
        </inertial>  
    </link>  
    <!-- Hip joint -->  
    <joint name="lf_haa_joint" type="revolute">
        <parent link="trunk"/>
        <child link="lf_hip"/>
        <origin xyz="0.277 0.116 0.0"/>    
        <axis xyz="1 0 0"/>    
        <limit command_effort="40" current="10" effort="80" gear_velocity="10" lower="-9.42" upper="9.42" velocity="15"/>    
        <dynamics damping="0.0" friction="0.0"/>  
    </joint>  
    <link name="lf_upperleg">
        <visual>      
            <origin rpy="0 0 0.0" xyz="0 0 0"/>      
            <geometry>        
                <mesh filename="package://anymal_description/meshes/anymal_thigh_l.dae" scale="0.001 0.001     0.001"/>
            </geometry>      
            <material name="anymal_material"/>    
        </visual>    
        <collision>      
            <!-- upperleg with heat fins -->
            <origin rpy="0.145 0 0" xyz="0 0.035 -0.125"/>      
            <geometry>        
                <box size="0.08 0.04 0.25"/>      
            </geometry>    
        </collision>    
        <collision>      
            <!-- KFE actuator -->      
            <origin rpy="1.57079632679 0 0" xyz="0.0 0.069 -0.25"/>      
            <geometry>        
                <cylinder length="0.12" radius="0.06"/>      
            </geometry>    
        </collision>    
        <collision>      
            <!-- upper protector -->      
            <origin rpy="1.71579632679 0 0" xyz="0 -0.005 0"/>      
            <geometry>        
                <cylinder length="0.12" radius="0.066"/>      
            </geometry>    
        </collision>    
        <inertial>      
            <origin rpy="0 0 0" xyz="-0.003897968082 0.054226618537 -0.214583373795"/>      
            <mass value="2.3"/>      
            <inertia ixx="0.0120367944369" ixy="6.762065206e-05" ixz="0.000287806340448" iyy="0.0120643637939" iyz="-0.00140610131218" izz="0.00249422574881"/>    
        </inertial>  
    </link>  
    <!-- upperleg joint -->
    <joint name="lf_hfe_joint" type="revolute">
        <parent link="lf_hip"/>
        <child link="lf_upperleg"/>
        <origin xyz="0.0635                    0.041                    0.0"/>    
        <axis xyz="0 1 0"/>    
        <limit command_effort="40" current="10" effort="80" gear_velocity="10" lower="-9.42" upper="9.42" velocity="15.0"/>    
        <dynamics damping="0.0" friction="0.0"/>  
    </joint>  
    <link name="lf_lowerleg">
        <visual>      
            <origin rpy="0 0 0.0" xyz="0 0 0"/>      
            <geometry>        
                <mesh filename="package://anymal_description/meshes/anymal_shank_l.dae" scale="0.001 0.001     0.001"/>
            </geometry>      
            <material name="anymal_material"/>    
        </visual>    
        <collision>      
            <origin rpy="0 1.57079632679 0" xyz="0.065 -0.015 0.01"/>      
            <geometry>        
                <box size="0.08 0.07 0.13"/>      
            </geometry>    
        </collision>    
        <inertial>      
            <origin rpy="0 0 0" xyz="0.030816858139 -0.004617229294 0.000893125713"/>      
            <mass value="0.207204302"/>      
            <inertia ixx="0.0002104880248" ixy="-5.6750980345e-05" ixz="1.0127699391e-05" iyy="0.000676270210023" iyz="-8.22869024e-07" izz="0.000545032674924"/>    
        </inertial>  
    </link>  
    <!-- lowerleg joint -->
    <joint name="lf_kfe_joint" type="revolute">
        <parent link="lf_upperleg"/>
        <child link="lf_lowerleg"/>
        <origin xyz="0.0 0.109 -0.25"/>    
        <axis xyz="0 1 0"/>    
        <limit command_effort="40" current="10" effort="80" gear_velocity="10" lower="-9.42" upper="9.42" velocity="15.0"/>    
        <dynamics damping="0.0" friction="0.0"/>  
    </joint>  
    <!-- lowerleg to Adapter joint -->
    <joint name="lf_lowerleg_to_adapter" type="fixed">
        <parent link="lf_lowerleg"/>
        <child link="lf_adapter"/>
        <origin rpy="0.0 0.0 0.0" xyz="0.1 -0.02 0.0"/>  
    </joint>  
    <!-- Adapter link -->  
    <link name="lf_adapter">
        <visual>      
            <origin rpy="0 0 0.0" xyz="0 0 0.032"/>      
            <geometry>        
                <mesh filename="package://anymal_description/meshes/anymal_foot.dae" scale="0.001 0.001     0.001"/>
            </geometry>      
            <material name="anymal_material"/>    
        </visual>    
        <collision>      
            <origin rpy="0 0 0" xyz="0 0 -0.160625"/>      
            <geometry>        
                <cylinder length="0.32125" radius="0.015"/>      
            </geometry>      
            <material name="anymal_material"/>    
        </collision>    
        <inertial>      
            <origin rpy="0 0 0" xyz="-8.66e-10 -1.472e-09 -0.244345749188"/>      
            <mass value="0.140170767"/>      
            <inertia ixx="0.00159938741862" ixy="-9.32e-13" ixz="1.039e-11" iyy="0.00159938741932" iyz="1.7563e-11" izz="5.4423177329e-05"/>    
        </inertial>  
    </link>  
    <!-- Adapter to Foot joint -->  
    <joint name="lf_adapter_to_foot" type="fixed">
        <parent link="lf_adapter"/>
        <child link="lf_foot"/>
        <origin rpy="0.0 0.0 0.0" xyz="0.0 0.0 -0.32125"/>  
    </joint>  
    <!-- Foot link -->  
    <link name="lf_foot">
        <collision>      
            <origin xyz="0 0 0.02325"/>      
            <geometry>        
                <sphere radius="0.031"/>      
            </geometry>    
        </collision>  
    </link>   
    <link name="rf_hip">
        <visual>      
            <origin rpy="0 0 0.0" xyz="0 0 0"/>      
            <geometry>        
                <mesh filename="package://anymal_description/meshes/anymal_hip_r.dae" scale="0.001 0.001     0.001"/>
            </geometry>      
            <material name="anymal_material"/>    
        </visual>    
        <collision>      
            <!-- Protector -->      
            <origin rpy="1.57079632679 0 0" xyz="0.0635 0.009 0.0"/>      
            <geometry>        
                <cylinder length="0.1" radius="0.08"/>      
            </geometry>    
        </collision>    
        <collision>      
            <!-- Heatfins -->      
            <origin rpy="1.57079632679 0 0" xyz="0.0635 0.074 0.0"/>      
            <geometry>        
                <cylinder length="0.03" radius="0.045"/>      
            </geometry>    
        </collision>    
        <inertial>      
            <origin rpy="0 0 0" xyz="0.064516258147 0.003787101702 -0.000152184388"/>      
            <mass value="1.42462064"/>      
            <inertia ixx="0.00243023349564" ixy="1.53023971e-05" ixz="-2.1819095354e-05" iyy="0.00230257239103" iyz="-2.6473021273e-05" izz="0.0019806759227"/>    
        </inertial>  
    </link>  
    <!-- Hip joint -->  
    <joint name="rf_haa_joint" type="revolute">
        <parent link="trunk"/>
        <child link="rf_hip"/>
        <origin xyz="0.277 -0.116 0.0"/>    
        <axis xyz="1 0 0"/>    
        <limit command_effort="40" current="10" effort="80" gear_velocity="10" lower="-9.42" upper="9.42" velocity="15"/>    
        <dynamics damping="0.0" friction="0.0"/>  
    </joint>  
    <link name="rf_upperleg">
        <visual>      
            <origin rpy="0 0 0.0" xyz="0 0 0"/>      
            <geometry>        
                <mesh filename="package://anymal_description/meshes/anymal_thigh_r.dae" scale="0.001 0.001     0.001"/>
            </geometry>      
            <material name="anymal_material"/>    
        </visual>    
        <collision>      
            <!-- upperleg with heat fins -->
            <origin rpy="-0.145 0 0" xyz="0 -0.035 -0.125"/>      
            <geometry>        
                <box size="0.08 0.04 0.25"/>      
            </geometry>    
        </collision>    
        <collision>      
            <!-- KFE actuator -->      
            <origin rpy="1.57079632679 0 0" xyz="0.0 -0.069 -0.25"/>      
            <geometry>        
                <cylinder length="0.12" radius="0.06"/>      
            </geometry>    
        </collision>    
        <collision>      
            <!-- upper protector -->      
            <origin rpy="-1.71579632679 0 0" xyz="0 0.005 0"/>      
            <geometry>        
                <cylinder length="0.12" radius="0.066"/>      
            </geometry>    
        </collision>    
        <inertial>      
            <origin rpy="0 0 0" xyz="-0.003897968082 -0.054226618537 -0.214583373795"/>      
            <mass value="2.3"/>      
            <inertia ixx="0.0120367944369" ixy="-6.762065206e-05" ixz="0.000287806340448" iyy="0.0120643637939" iyz="0.00140610131218" izz="0.00249422574881"/>    
        </inertial>  
    </link>  
    <!-- upperleg joint -->
    <joint name="rf_hfe_joint" type="revolute">
        <parent link="rf_hip"/>
        <child link="rf_upperleg"/>
        <origin xyz="0.0635                    -0.041                    0.0"/>    
        <axis xyz="0 1 0"/>    
        <limit command_effort="40" current="10" effort="80" gear_velocity="10" lower="-9.42" upper="9.42" velocity="15.0"/>    
        <dynamics damping="0.0" friction="0.0"/>  
    </joint>  
    <link name="rf_lowerleg">
        <visual>      
            <origin rpy="0 0 0.0" xyz="0 0 0"/>      
            <geometry>        
                <mesh filename="package://anymal_description/meshes/anymal_shank_r.dae" scale="0.001 0.001     0.001"/>
            </geometry>      
            <material name="anymal_material"/>    
        </visual>    
        <collision>      
            <origin rpy="0 1.57079632679 0" xyz="0.065 0.015 0.01"/>      
            <geometry>        
                <box size="0.08 0.07 0.13"/>      
            </geometry>    
        </collision>    
        <inertial>      
            <origin rpy="0 0 0" xyz="0.030816858139 0.004617229294 0.000893125713"/>      
            <mass value="0.207204302"/>      
            <inertia ixx="0.0002104880248" ixy="5.6750980345e-05" ixz="1.0127699391e-05" iyy="0.000676270210023" iyz="8.22869024e-07" izz="0.000545032674924"/>    
        </inertial>  
    </link>  
    <!-- lowerleg joint -->
    <joint name="rf_kfe_joint" type="revolute">
        <parent link="rf_upperleg"/>
        <child link="rf_lowerleg"/>
        <origin xyz="0.0 -0.109 -0.25"/>    
        <axis xyz="0 1 0"/>    
        <limit command_effort="40" current="10" effort="80" gear_velocity="10" lower="-9.42" upper="9.42" velocity="15.0"/>    
        <dynamics damping="0.0" friction="0.0"/>  
    </joint>  
    <!-- lowerleg to Adapter joint -->
    <joint name="rf_lowerleg_to_adapter" type="fixed">
        <parent link="rf_lowerleg"/>
        <child link="rf_adapter"/>
        <origin rpy="-0.0 0.0 -0.0" xyz="0.1 0.02 0.0"/>  
    </joint>  
    <!-- Adapter link -->  
    <link name="rf_adapter">
        <visual>      
            <origin rpy="0 0 0.0" xyz="0 0 0.032"/>      
            <geometry>        
                <mesh filename="package://anymal_description/meshes/anymal_foot.dae" scale="0.001 0.001     0.001"/>
            </geometry>      
            <material name="anymal_material"/>    
        </visual>    
        <collision>      
            <origin rpy="0 0 0" xyz="0 0 -0.160625"/>      
            <geometry>        
                <cylinder length="0.32125" radius="0.015"/>      
            </geometry>      
            <material name="anymal_material"/>    
        </collision>    
        <inertial>      
            <origin rpy="0 0 0" xyz="-8.66e-10 -1.472e-09 -0.244345749188"/>      
            <mass value="0.140170767"/>      
            <inertia ixx="0.00159938741862" ixy="-9.32e-13" ixz="1.039e-11" iyy="0.00159938741932" iyz="1.7563e-11" izz="5.4423177329e-05"/>    
        </inertial>  
    </link>  
    <!-- Adapter to Foot joint -->  
    <joint name="rf_adapter_to_foot" type="fixed">
        <parent link="rf_adapter"/>
        <child link="rf_foot"/>
        <origin rpy="-0.0 0.0 -0.0" xyz="0.0 -0.0 -0.32125"/>  
    </joint>  
    <!-- Foot link -->  
    <link name="rf_foot">
        <collision>      
            <origin xyz="0 0 0.02325"/>      
            <geometry>        
                <sphere radius="0.031"/>      
            </geometry>    
        </collision>  
    </link>  
    <link name="lh_hip">
        <visual>      
            <origin rpy="0 0 -3.14159265359" xyz="0 0 0"/>      
            <geometry>        
                <mesh filename="package://anymal_description/meshes/anymal_hip_r.dae" scale="0.001 0.001     0.001"/>
            </geometry>      
            <material name="anymal_material"/>    
        </visual>    
        <collision>      
            <!-- Protector -->      
            <origin rpy="-1.57079632679 0 0" xyz="-0.0635 -0.009 0.0"/>      
            <geometry>        
                <cylinder length="0.1" radius="0.08"/>      
            </geometry>    
        </collision>    
        <collision>      
            <!-- Heatfins -->      
            <origin rpy="-1.57079632679 0 0" xyz="-0.0635 -0.074 0.0"/>      
            <geometry>        
                <cylinder length="0.03" radius="0.045"/>      
            </geometry>    
        </collision>    
        <inertial>      
            <origin rpy="0 0 0" xyz="-0.064516258147 -0.003787101702 -0.000152184388"/>      
            <mass value="1.42462064"/>      
            <inertia ixx="0.00243023349564" ixy="1.53023971e-05" ixz="2.1819095354e-05" iyy="0.00230257239103" iyz="2.6473021273e-05" izz="0.0019806759227"/>    
        </inertial>  
    </link>  
    <!-- Hip joint -->  
    <joint name="lh_haa_joint" type="revolute">
        <parent link="trunk"/>
        <child link="lh_hip"/>
        <origin xyz="-0.277 0.116 0.0"/>    
        <axis xyz="1 0 0"/>    
        <limit command_effort="40" current="10" effort="80" gear_velocity="10" lower="-9.42" upper="9.42" velocity="15"/>    
        <dynamics damping="0.0" friction="0.0"/>  
    </joint>  
    <link name="lh_upperleg">
        <visual>      
            <origin rpy="0 0 -3.14159265359" xyz="0 0 0"/>      
            <geometry>        
                <mesh filename="package://anymal_description/meshes/anymal_thigh_r.dae" scale="0.001 0.001     0.001"/>
            </geometry>      
            <material name="anymal_material"/>    
        </visual>    
        <collision>      
            <!-- upperleg with heat fins -->
            <origin rpy="0.145 0 0" xyz="0 0.035 -0.125"/>      
            <geometry>        
                <box size="0.08 0.04 0.25"/>      
            </geometry>    
        </collision>    
        <collision>      
            <!-- KFE actuator -->      
            <origin rpy="1.57079632679 0 0" xyz="0.0 0.069 -0.25"/>      
            <geometry>        
                <cylinder length="0.12" radius="0.06"/>      
            </geometry>    
        </collision>    
        <collision>      
            <!-- upper protector -->      
            <origin rpy="1.71579632679 0 0" xyz="0 -0.005 0"/>      
            <geometry>        
                <cylinder length="0.12" radius="0.066"/>      
            </geometry>    
        </collision>    
        <inertial>      
            <origin rpy="0 0 0" xyz="0.003897968082 0.054226618537 -0.214583373795"/>      
            <mass value="2.3"/>      
            <inertia ixx="0.0120367944369" ixy="-6.762065206e-05" ixz="-0.000287806340448" iyy="0.0120643637939" iyz="-0.00140610131218" izz="0.00249422574881"/>    
        </inertial>  
    </link>  
    <!-- upperleg joint -->
    <joint name="lh_hfe_joint" type="revolute">
        <parent link="lh_hip"/>
        <child link="lh_upperleg"/>
        <origin xyz="-0.0635                    0.041                    0.0"/>    
        <axis xyz="0 1 0"/>    
        <limit command_effort="40" current="10" effort="80" gear_velocity="10" lower="-9.42" upper="9.42" velocity="15.0"/>    
        <dynamics damping="0.0" friction="0.0"/>  
    </joint>  
    <link name="lh_lowerleg">
        <visual>      
            <origin rpy="0 0 -3.14159265359" xyz="0 0 0"/>      
            <geometry>        
                <mesh filename="package://anymal_description/meshes/anymal_shank_r.dae" scale="0.001 0.001     0.001"/>
            </geometry>      
            <material name="anymal_material"/>    
        </visual>    
        <collision>      
            <origin rpy="0 1.57079632679 0" xyz="-0.065 -0.015 0.01"/>      
            <geometry>        
                <box size="0.08 0.07 0.13"/>      
            </geometry>    
        </collision>    
        <inertial>      
            <origin rpy="0 0 0" xyz="-0.030816858139 -0.004617229294 0.000893125713"/>      
            <mass value="0.207204302"/>      
            <inertia ixx="0.0002104880248" ixy="5.6750980345e-05" ixz="-1.0127699391e-05" iyy="0.000676270210023" iyz="-8.22869024e-07" izz="0.000545032674924"/>    
        </inertial>  
    </link>  
    <!-- lowerleg joint -->
    <joint name="lh_kfe_joint" type="revolute">
        <parent link="lh_upperleg"/>
        <child link="lh_lowerleg"/>
        <origin xyz="-0.0 0.109 -0.25"/>    
        <axis xyz="0 1 0"/>    
        <limit command_effort="40" current="10" effort="80" gear_velocity="10" lower="-9.42" upper="9.42" velocity="15.0"/>    
        <dynamics damping="0.0" friction="0.0"/>  
    </joint>  
    <!-- lowerleg to Adapter joint -->
    <joint name="lh_lowerleg_to_adapter" type="fixed">
        <parent link="lh_lowerleg"/>
        <child link="lh_adapter"/>
        <origin rpy="0.0 -0.0 -0.0" xyz="-0.1 -0.02 0.0"/>  
    </joint>  
    <!-- Adapter link -->  
    <link name="lh_adapter">
        <visual>      
            <origin rpy="0 0 -3.14159265359" xyz="0 0 0.032"/>      
            <geometry>        
                <mesh filename="package://anymal_description/meshes/anymal_foot.dae" scale="0.001 0.001     0.001"/>
            </geometry>      
            <material name="anymal_material"/>    
        </visual>    
        <collision>      
            <origin rpy="0 0 0" xyz="0 0 -0.160625"/>      
            <geometry>        
                <cylinder length="0.32125" radius="0.015"/>      
            </geometry>      
            <material name="anymal_material"/>    
        </collision>    
        <inertial>      
            <origin rpy="0 0 0" xyz="-8.66e-10 -1.472e-09 -0.244345749188"/>      
            <mass value="0.140170767"/>      
            <inertia ixx="0.00159938741862" ixy="-9.32e-13" ixz="1.039e-11" iyy="0.00159938741932" iyz="1.7563e-11" izz="5.4423177329e-05"/>    
        </inertial>  
    </link>  
    <!-- Adapter to Foot joint -->  
    <joint name="lh_adapter_to_foot" type="fixed">
        <parent link="lh_adapter"/>
        <child link="lh_foot"/>
        <origin rpy="0.0 -0.0 -0.0" xyz="-0.0 0.0 -0.32125"/>  
    </joint>  
    <!-- Foot link -->  
    <link name="lh_foot">
        <collision>      
            <origin xyz="0 0 0.02325"/>      
            <geometry>        
                <sphere radius="0.031"/>      
            </geometry>    
        </collision>  
    </link>  
    <link name="rh_hip">
        <visual>      
            <origin rpy="0 0 -3.14159265359" xyz="0 0 0"/>      
            <geometry>        
                <mesh filename="package://anymal_description/meshes/anymal_hip_l.dae" scale="0.001 0.001     0.001"/>
            </geometry>      
            <material name="anymal_material"/>    
        </visual>    
        <collision>      
            <!-- Protector -->      
            <origin rpy="-1.57079632679 0 0" xyz="-0.0635 0.009 0.0"/>      
            <geometry>        
                <cylinder length="0.1" radius="0.08"/>      
            </geometry>    
        </collision>    
        <collision>      
            <!-- Heatfins -->      
            <origin rpy="-1.57079632679 0 0" xyz="-0.0635 0.074 0.0"/>      
            <geometry>        
                <cylinder length="0.03" radius="0.045"/>      
            </geometry>    
        </collision>    
        <inertial>      
            <origin rpy="0 0 0" xyz="-0.064516258147 0.003787101702 -0.000152184388"/>      
            <mass value="1.42462064"/>      
            <inertia ixx="0.00243023349564" ixy="-1.53023971e-05" ixz="2.1819095354e-05" iyy="0.00230257239103" iyz="-2.6473021273e-05" izz="0.0019806759227"/>    
        </inertial>  
    </link>  
    <!-- Hip joint -->  
    <joint name="rh_haa_joint" type="revolute">
        <parent link="trunk"/>
        <child link="rh_hip"/>
        <origin xyz="-0.277 -0.116 0.0"/>    
        <axis xyz="1 0 0"/>    
        <limit command_effort="40" current="10" effort="80" gear_velocity="10" lower="-9.42" upper="9.42" velocity="15"/>    
        <dynamics damping="0.0" friction="0.0"/>  
    </joint>  
    <link name="rh_upperleg">
        <visual>      
            <origin rpy="0 0 -3.14159265359" xyz="0 0 0"/>      
            <geometry>        
                <mesh filename="package://anymal_description/meshes/anymal_thigh_l.dae" scale="0.001 0.001     0.001"/>
            </geometry>      
            <material name="anymal_material"/>    
        </visual>    
        <collision>      
            <!-- upperleg with heat fins -->
            <origin rpy="-0.145 0 0" xyz="0 -0.035 -0.125"/>      
            <geometry>        
                <box size="0.08 0.04 0.25"/>      
            </geometry>    
        </collision>    
        <collision>      
            <!-- KFE actuator -->      
            <origin rpy="1.57079632679 0 0" xyz="0.0 -0.069 -0.25"/>      
            <geometry>        
                <cylinder length="0.12" radius="0.06"/>      
            </geometry>    
        </collision>    
        <collision>      
            <!-- upper protector -->      
            <origin rpy="-1.71579632679 0 0" xyz="0 0.005 0"/>      
            <geometry>        
                <cylinder length="0.12" radius="0.066"/>      
            </geometry>    
        </collision>    
        <inertial>      
            <origin rpy="0 0 0" xyz="0.003897968082 -0.054226618537 -0.214583373795"/>      
            <mass value="2.3"/>      
            <inertia ixx="0.0120367944369" ixy="6.762065206e-05" ixz="-0.000287806340448" iyy="0.0120643637939" iyz="0.00140610131218" izz="0.00249422574881"/>    
        </inertial>  
    </link>  
    <!-- upperleg joint -->
    <joint name="rh_hfe_joint" type="revolute">
        <parent link="rh_hip"/>
        <child link="rh_upperleg"/>
        <origin xyz="-0.0635                    -0.041                    0.0"/>    
        <axis xyz="0 1 0"/>    
        <limit command_effort="40" current="10" effort="80" gear_velocity="10" lower="-9.42" upper="9.42" velocity="15.0"/>    
        <dynamics damping="0.0" friction="0.0"/>  
    </joint>  
    <link name="rh_lowerleg">
        <visual>      
            <origin rpy="0 0 -3.14159265359" xyz="0 0 0"/>      
            <geometry>        
                <mesh filename="package://anymal_description/meshes/anymal_shank_l.dae" scale="0.001 0.001     0.001"/>
            </geometry>      
            <material name="anymal_material"/>    
        </visual>    
        <collision>      
            <origin rpy="0 1.57079632679 0" xyz="-0.065 0.015 0.01"/>      
            <geometry>        
                <box size="0.08 0.07 0.13"/>      
            </geometry>    
        </collision>    
        <inertial>      
            <origin rpy="0 0 0" xyz="-0.030816858139 0.004617229294 0.000893125713"/>      
            <mass value="0.207204302"/>      
            <inertia ixx="0.0002104880248" ixy="-5.6750980345e-05" ixz="-1.0127699391e-05" iyy="0.000676270210023" iyz="8.22869024e-07" izz="0.000545032674924"/>    
        </inertial>  
    </link>  
    <!-- lowerleg joint -->
    <joint name="rh_kfe_joint" type="revolute">
        <parent link="rh_upperleg"/>
        <child link="rh_lowerleg"/>
        <origin xyz="-0.0 -0.109 -0.25"/>    
        <axis xyz="0 1 0"/>    
        <limit command_effort="40" current="10" effort="80" gear_velocity="10" lower="-9.42" upper="9.42" velocity="15.0"/>    
        <dynamics damping="0.0" friction="0.0"/>  
    </joint>  
    <!-- lowerleg to Adapter joint -->
    <joint name="rh_lowerleg_to_adapter" type="fixed">
        <parent link="rh_lowerleg"/>
        <child link="rh_adapter"/>
        <origin rpy="-0.0 -0.0 0.0" xyz="-0.1 0.02 0.0"/>  
    </joint>  
    <!-- Adapter link -->  
    <link name="rh_adapter">
        <visual>      
            <origin rpy="0 0 -3.14159265359" xyz="0 0 0.032"/>      
            <geometry>        
                <mesh filename="package://anymal_description/meshes/anymal_foot.dae" scale="0.001 0.001     0.001"/>
            </geometry>      
            <material name="anymal_material"/>    
        </visual>    
        <collision>      
            <origin rpy="0 0 0" xyz="0 0 -0.160625"/>      
            <geometry>        
                <cylinder length="0.32125" radius="0.015"/>      
            </geometry>      
            <material name="anymal_material"/>    
        </collision>    
        <inertial>      
            <origin rpy="0 0 0" xyz="-8.66e-10 -1.472e-09 -0.244345749188"/>      
            <mass value="0.140170767"/>      
            <inertia ixx="0.00159938741862" ixy="-9.32e-13" ixz="1.039e-11" iyy="0.00159938741932" iyz="1.7563e-11" izz="5.4423177329e-05"/>    
        </inertial>  
    </link>  
    <!-- Adapter to Foot joint -->  
    <joint name="rh_adapter_to_foot" type="fixed">
        <parent link="rh_adapter"/>
        <child link="rh_foot"/>
        <origin rpy="-0.0 -0.0 0.0" xyz="-0.0 -0.0 -0.32125"/>  
    </joint>  
    <!-- Foot link -->  
    <link name="rh_foot">
        <collision>      
            <origin xyz="0 0 0.02325"/>      
            <geometry>        
                <sphere radius="0.031"/>      
            </geometry>    
        </collision>  
    </link>   

    <!-- Extensions -->
    <xacro:leg_transmission prefix="rf"/>
    <xacro:leg_gazebo prefix="rf" robot_name="$(arg robot_name)" load_force_sensors="$(arg load_force_sensors)"/>
    <xacro:leg_transmission prefix="lf"/>
    <xacro:leg_gazebo prefix="lf" robot_name="$(arg robot_name)" load_force_sensors="$(arg load_force_sensors)"/>
    <xacro:leg_transmission prefix="rh"/>
    <xacro:leg_gazebo prefix="rh" robot_name="$(arg robot_name)" load_force_sensors="$(arg load_force_sensors)"/>
    <xacro:leg_transmission prefix="lh"/>
    <xacro:leg_gazebo prefix="lh" robot_name="$(arg robot_name)" load_force_sensors="$(arg load_force_sensors)"/>

</robot>
