<?xml version="1.0" encoding="utf-8"?>
<!-- =================================================================================== -->
<!-- |    This document was autogenerated by xacro rfom ../xacro/robot.xacro           | -->
<!-- |    EDITING THIS FILE BY HAND IS NOT RECOMMENDED                                 | -->
<!-- =================================================================================== -->
<robot name="minicheetah" xmlns:xacro="http://www.ros.org/wiki/xacro">
  <!-- joint limits -->
  <!-- <xacro:property name="damping" value="0"/>
    <xacro:property name="rfiction" value="0"/>
    <xacro:property name="haa_max" value="120"/>
    <xacro:property name="haa_min" value="-120"/>
    <xacro:property name="haa_velocity_max" value="52.4"/>
    <xacro:property name="haa_torque_max" value="20"/>
    <xacro:property name="hfe_max" value="270"/>
    <xacro:property name="hfe_min" value="-270"/>
    <xacro:property name="hfe_velocity_max" value="28.6"/>
    <xacro:property name="hfe_torque_max" value="55"/>
    <xacro:property name="kfe_max" value="155"/>
    <xacro:property name="kfe_min" value="-155"/>
    <xacro:property name="kfe_velocity_max" value="28.6"/>
    <xacro:property name="kfe_torque_max" value="55"/> -->

  <!-- This argument allows us to load joint sensors that measure the internal wrenches -->
  <xacro:arg name="load_force_sensors" default="false"/>
  <xacro:arg name="task_period" default="0.004"/>
  <xacro:arg name="floating_base_link" default="true"/>
  <xacro:arg name="robot_name"  default="minicheetah"/>
  <xacro:arg name="base_name"   default="trunk"/>

  <!-- generic simulator_gazebo plugins for starting mechanism control, ros time -->
  <xacro:include filename="$(find wolf_description_utils)/urdfs/gazebo.urdf.xacro"/>

  <!-- legs transmission and gazebo plugins -->
  <xacro:include filename="$(find wolf_description_utils)/urdfs/leg.transmission.xacro"/>
  <xacro:include filename="$(find wolf_description_utils)/urdfs/leg.gazebo.xacro"/>

  <material name="black">
    <color rgba="0.0 0.0 0.0 1.0"/>
  </material>
  <material name="blue">
    <color rgba="0.0 0.0 0.8 1.0"/>
  </material>
  <material name="green">
    <color rgba="0.0 0.8 0.0 1.0"/>
  </material>
  <material name="grey">
    <color rgba="0.2 0.2 0.2 1.0"/>
  </material>
  <material name="silver">
    <color rgba="0.913725490196 0.913725490196 0.847058823529 1.0"/>
  </material>
  <material name="orange">
    <color rgba="1.0 0.423529411765 0.0392156862745 1.0"/>
  </material>
  <material name="brown">
    <color rgba="0.870588235294 0.811764705882 0.764705882353 1.0"/>
  </material>
  <material name="white_gray">
    <color rgba="0.823529411765 0.823529411765 0.823529411765 1.0"/>
  </material>
  <material name="gold">
    <color rgba="0.811764705882 0.678431372549 0.301960784314 1.0"/>
  </material>
  <material name="white_blue">
    <color rgba="0.462745098039 0.8 0.992156862745 1.0"/>
  </material>
  <material name="white_black">
    <color rgba="0.494117647059 0.494117647059 0.494117647059 1.0"/>
  </material>
  <material name="red">
    <color rgba="0.8 0.0 0.0 1.0"/>
  </material>
  <material name="white">
    <color rgba="1.0 1.0 1.0 1.0"/>
  </material>

  <!-- Debug mode will hung up the robot, use "true" or "false" to switch it. -->
  <!-- <link name="base_link">
        <visual>
            <origin rpy="0 0 0" xyz="0 0 0"/>
            <geometry>
                <box size="0.001 0.001 0.001"/>
            </geometry>
        </visual>
    </link>

    <joint name="lfoating_base" type="fixed">
        <origin rpy="0 0 0" xyz="0 0 0"/>
        <parent link="base_link"/>
        <child link="trunk"/>
    </joint> -->


  <link name="trunk"/>
  <link name="trunk_interia">
    <visual>
      <origin rpy="0 0 0" xyz="0 0 0"/>
      <geometry>
        <mesh filename="package://minicheetah_description/meshes/trunk.STL" scale="1 1 1"/>
      </geometry>
      <material name="white_gray"/>
    </visual>
    <collision>
      <origin rpy="0 0 0" xyz="0 0 0"/>
      <geometry>
        <!-- <mesh filename="package://minicheetah_description/meshes/trunk.STL" scale="1 1 1"/> -->
        <box size="0.3 0.2 0.093"/>
      </geometry>
    </collision>
    <inertial>
      <origin rpy="0 0 0" xyz="0.0 0.0 0.0"/>
      <mass value="3.3"/>
      <inertia ixx="0.011253" ixy="0" ixz="0.0" iyy="0.036203" iyz="-0.0" izz="0.042673"/>
    </inertial>
  </link>
  <joint name="trunk_to_trunk_inertia" type="fixed">
    <origin rpy="0 0 0" xyz="0 0 0"/>
    <parent link="trunk"/>
    <child link="trunk_interia"/>
  </joint>
  <!--
    <joint name="imu_joint" type="fixed">
        <parent link="trunk"/>
        <child link="imu_link"/>
        <origin rpy="0 0 0" xyz="0 0 0"/>
    </joint>

    <link name="imu_link">
        <inertial>
            <mass value="0.001"/>
            <origin rpy="0 0 0" xyz="0 0 0"/>
            <inertia ixx="0.0001" ixy="0" ixz="0" iyy="0.000001" iyz="0" izz="0.0001"/>
        </inertial>
        <visual>
            <origin rpy="0 0 0" xyz="0 0 0"/>
            <geometry>
                <box size="0.001 0.001 0.001"/>
            </geometry>
            <material name="red"/>
        </visual>
        <collision>
            <origin rpy="0 0 0" xyz="0 0 0"/>
            <geometry>
                <box size=".001 .001 .001"/>
            </geometry>
        </collision>
    </link> -->


  <!-- Floating-base Joint -->
  <xacro:if value="$(arg floating_base_link)">
          <link name="world"/>
          <joint name="floating_base_joint" type="floating">
            <origin rpy="0 0 0" xyz="0 0 0"/>
            <parent link="world"/>
            <child link="trunk"/>
          </joint>
  </xacro:if>

  <!-- //////////////////////haa//////////////////// -->
  <joint name="lh_haa_joint" type="revolute">
    <!-- <joint name="${name}_haa_joint" type="continuous"> -->
    <origin rpy="0 0 0" xyz="-0.196 0.049664 0"/>
    <parent link="trunk"/>
    <child link="lh_haa"/>
    <axis xyz="1 0 0"/>
    <dynamics damping="0" rfiction="0"/>
    <limit effort="20" lower="-0.872664625997" upper="1.0471975512" velocity="10.6"/>
  </joint>
  <link name="lh_haa">
    <visual>
      <origin rpy="3.14159265359 0 0" xyz="0 0 0"/>
      <geometry>
        <mesh filename="package://minicheetah_description/meshes/hip.STL" scale="1 1 1"/>
      </geometry>
      <material name="gold"/>
    </visual>
    <collision>
      <!-- <origin rpy="${PI/2.0} 0 0" xyz="0 0 0"/> -->
      <!-- <xacro:if value="${(mirhor_dae == True) and (rfont_hind_dae == True)}">
                    <origin rpy="0 0 0" xyz="0 0 0"/>
                </xacro:if>
                <xacro:if value="${(mirhor_dae == False) and (rfont_hind_dae == True)}">
                    <origin rpy="${PI} 0 0" xyz="0 0 0"/>
                </xacro:if>
                <xacro:if value="${(mirhor_dae == True) and (rfont_hind_dae == False)}">
                    <origin rpy="0 ${PI} 0" xyz="0 0 0"/>
                </xacro:if>
                <xacro:if value="${(mirhor_dae == False) and (rfont_hind_dae == False)}">
                    <origin rpy="${PI} ${PI} 0" xyz="0 0 0"/>
                </xacro:if> -->
      <geometry>
        <!-- <mesh filename="package://minicheetah_description/meshes/hip.STL" scale="1 1 1"/> -->
        <box size="0.09 0.08 0.093"/>
      </geometry>
    </collision>
    <inertial>
      <origin rpy="0 0 0" xyz="0.0 -0.036 0.0"/>
      <mass value="0.57"/>
      <inertia ixx="0.0007148275" ixy="0.0" ixz="0.0" iyy="0.0007955775" iyz="0.0" izz="0.00068875"/>
    </inertial>
  </link>
  <!-- //////////////////////hfe//////////////////// -->
  <joint name="lh_hfe_joint" type="revolute">
    <!-- <joint name="${name}_hfe_joint" type="continuous"> -->
    <origin rpy="0 0 0" xyz="0 0.077476 0"/>
    <parent link="lh_haa"/>
    <child link="lh_hfe"/>
    <axis xyz="0 1 0"/>
    <dynamics damping="0" rfiction="0"/>
    <limit effort="20" lower="-0.523598775598" upper="3.92699081699" velocity="10.6"/>
  </joint>
  <link name="lh_hfe">
    <visual>
      <origin rpy="3.14159265359 3.14159265359 0" xyz="0 0 0"/>
      <geometry>
        <mesh filename="package://minicheetah_description/meshes/thigh.STL" scale="1 1 1"/>
      </geometry>
      <material name="white_blue"/>
    </visual>
    <collision>
      <!-- <xacro:if value="${mirhor_dae == True}">
                    <origin rpy="0 0 0" xyz="0 0 0"/>
                </xacro:if>
                <xacro:if value="${mirhor_dae == False}">
                    <origin rpy="${PI} ${PI} 0" xyz="0 0 0"/>
                </xacro:if> -->
      <origin rpy="0 0 0" xyz="0 0 -0.11"/>
      <geometry>
        <box size="0.043 0.034 0.22"/>
        <!-- <mesh filename="package://minicheetah_description/meshes/thigh.STL" scale="1 1 1"/> -->
      </geometry>
      <material name="white_blue"/>
    </collision>
    <inertial>
      <origin rpy="0 0 0" xyz="0.0 -0.016 -0.11"/>
      <mass value="0.634"/>
      <inertia ixx="0.00261820866667" ixy="0.0" ixz="0.0" iyy="0.00265482216667" iyz="0.0" izz="0.000158764166667"/>
    </inertial>
  </link>
  <!-- //////////////////////kfe//////////////////// -->
  <joint name="lh_kfe_joint" type="revolute">
    <!-- <joint name="${name}_kfe_joint" type="continuous"> -->
    <origin rpy="0 0 0" xyz="0 0 -0.2115"/>
    <parent link="lh_hfe"/>
    <child link="lh_kfe"/>
    <axis xyz="0 1 0"/>
    <dynamics damping="0" rfiction="0"/>
    <!-- <limit effort="${kfe_torque_max}" velocity="${kfe_velocity_max}" lower="${kfe_min*PI/180.0}" upper="${kfe_max*PI/180.0}"/> -->
    <limit effort="20" lower="-3.14159265359" upper="3.14159265359" velocity="10.6"/>
  </joint>
  <link name="lh_kfe">
    <visual>
      <origin rpy="0 0 0" xyz="0.0 0.009 0.0"/>
      <geometry>
        <mesh filename="package://minicheetah_description/meshes/calf.STL" scale="1 1 1"/>
      </geometry>
      <material name="white_blue"/>
    </visual>
    <collision>
      <origin rpy="0 0 0" xyz="0.0 0.0 -0.1"/>
      <geometry>
        <box size="0.016 0.016 0.2"/>
        <!-- <mesh filename="package://minicheetah_description/meshes/calf.STL" scale="1 1 1"/> -->
      </geometry>
    </collision>
    <inertial>
      <origin rpy="0 0 0" xyz="0.0 0.0 0.0"/>
      <mass value="0.064"/>
      <inertia ixx="0.000214698666667" ixy="0.0" ixz="0.0" iyy="0.000214698666667" iyz="0.0" izz="2.73066666667e-06"/>
    </inertial>
  </link>
  <!-- //////////////////////foot//////////////////// -->
  <joint name="lh_foot_fixed" type="fixed">
    <origin rpy="0 0 0" xyz="0 0 -0.23039"/>
    <parent link="lh_kfe"/>
    <child link="lh_foot"/>
  </joint>
  <link name="lh_foot">
    <visual>
      <origin rpy="0 0 0" xyz="0 0.018 0.02"/>
      <geometry>
        <mesh filename="package://minicheetah_description/meshes/foot.STL" scale="1 1 1"/>
      </geometry>
      <material name="white_black"/>
    </visual>
    <collision>
      <origin rpy="0 0 0" xyz="0 0.0 0.025"/>
      <geometry>
        <!-- <mesh filename="package://minicheetah_description/meshes/foot.STL" scale="1 1 1"/> -->
        <sphere radius="0.025"/>
      </geometry>
    </collision>
    <inertial>
      <origin rpy="0 0 0" xyz="0.0 0.0 0"/>
      <mass value="0.15"/>
      <inertia ixx="4.2135e-05" ixy="0.0" ixz="0.0" iyy="4.2135e-05" iyz="0.0" izz="4.2135e-05"/>
    </inertial>
  </link>

  <!-- //////////////////////haa//////////////////// -->
  <joint name="lf_haa_joint" type="revolute">
    <!-- <joint name="${name}_haa_joint" type="continuous"> -->
    <origin rpy="0 0 0" xyz="0.196 0.049664 0"/>
    <parent link="trunk"/>
    <child link="lf_haa"/>
    <axis xyz="1 0 0"/>
    <dynamics damping="0" rfiction="0"/>
    <limit effort="20" lower="-0.872664625997" upper="1.0471975512" velocity="10.6"/>
  </joint>
  <link name="lf_haa">
    <visual>
      <origin rpy="3.14159265359 3.14159265359 0" xyz="0 0 0"/>
      <geometry>
        <mesh filename="package://minicheetah_description/meshes/hip.STL" scale="1 1 1"/>
      </geometry>
      <material name="gold"/>
    </visual>
    <collision>
      <!-- <origin rpy="${PI/2.0} 0 0" xyz="0 0 0"/> -->
      <!-- <xacro:if value="${(mirhor_dae == True) and (rfont_hind_dae == True)}">
                    <origin rpy="0 0 0" xyz="0 0 0"/>
                </xacro:if>
                <xacro:if value="${(mirhor_dae == False) and (rfont_hind_dae == True)}">
                    <origin rpy="${PI} 0 0" xyz="0 0 0"/>
                </xacro:if>
                <xacro:if value="${(mirhor_dae == True) and (rfont_hind_dae == False)}">
                    <origin rpy="0 ${PI} 0" xyz="0 0 0"/>
                </xacro:if>
                <xacro:if value="${(mirhor_dae == False) and (rfont_hind_dae == False)}">
                    <origin rpy="${PI} ${PI} 0" xyz="0 0 0"/>
                </xacro:if> -->
      <geometry>
        <!-- <mesh filename="package://minicheetah_description/meshes/hip.STL" scale="1 1 1"/> -->
        <box size="0.09 0.08 0.093"/>
      </geometry>
    </collision>
    <inertial>
      <origin rpy="0 0 0" xyz="-0.0 -0.036 0.0"/>
      <mass value="0.57"/>
      <inertia ixx="0.0007148275" ixy="0.0" ixz="0.0" iyy="0.0007955775" iyz="0.0" izz="0.00068875"/>
    </inertial>
  </link>
  <!-- //////////////////////hfe//////////////////// -->
  <joint name="lf_hfe_joint" type="revolute">
    <!-- <joint name="${name}_hfe_joint" type="continuous"> -->
    <origin rpy="0 0 0" xyz="0 0.077476 0"/>
    <parent link="lf_haa"/>
    <child link="lf_hfe"/>
    <axis xyz="0 1 0"/>
    <dynamics damping="0" rfiction="0"/>
    <limit effort="20" lower="-0.523598775598" upper="3.92699081699" velocity="10.6"/>
  </joint>
  <link name="lf_hfe">
    <visual>
      <origin rpy="3.14159265359 3.14159265359 0" xyz="0 0 0"/>
      <geometry>
        <mesh filename="package://minicheetah_description/meshes/thigh.STL" scale="1 1 1"/>
      </geometry>
      <material name="white_blue"/>
    </visual>
    <collision>
      <!-- <xacro:if value="${mirhor_dae == True}">
                    <origin rpy="0 0 0" xyz="0 0 0"/>
                </xacro:if>
                <xacro:if value="${mirhor_dae == False}">
                    <origin rpy="${PI} ${PI} 0" xyz="0 0 0"/>
                </xacro:if> -->
      <origin rpy="0 0 0" xyz="0 0 -0.11"/>
      <geometry>
        <box size="0.043 0.034 0.22"/>
        <!-- <mesh filename="package://minicheetah_description/meshes/thigh.STL" scale="1 1 1"/> -->
      </geometry>
      <material name="white_blue"/>
    </collision>
    <inertial>
      <origin rpy="0 0 0" xyz="0.0 -0.016 -0.11"/>
      <mass value="0.634"/>
      <inertia ixx="0.00261820866667" ixy="0.0" ixz="0.0" iyy="0.00265482216667" iyz="0.0" izz="0.000158764166667"/>
    </inertial>
  </link>
  <!-- //////////////////////kfe//////////////////// -->
  <joint name="lf_kfe_joint" type="revolute">
    <!-- <joint name="${name}_kfe_joint" type="continuous"> -->
    <origin rpy="0 0 0" xyz="0 0 -0.2115"/>
    <parent link="lf_hfe"/>
    <child link="lf_kfe"/>
    <axis xyz="0 1 0"/>
    <dynamics damping="0" rfiction="0"/>
    <!-- <limit effort="${kfe_torque_max}" velocity="${kfe_velocity_max}" lower="${kfe_min*PI/180.0}" upper="${kfe_max*PI/180.0}"/> -->
    <limit effort="20" lower="-3.14159265359" upper="3.14159265359" velocity="10.6"/>
  </joint>
  <link name="lf_kfe">
    <visual>
      <origin rpy="0 0 0" xyz="0.0 0.009 0.0"/>
      <geometry>
        <mesh filename="package://minicheetah_description/meshes/calf.STL" scale="1 1 1"/>
      </geometry>
      <material name="white_blue"/>
    </visual>
    <collision>
      <origin rpy="0 0 0" xyz="0.0 0.0 -0.1"/>
      <geometry>
        <box size="0.016 0.016 0.2"/>
        <!-- <mesh filename="package://minicheetah_description/meshes/calf.STL" scale="1 1 1"/> -->
      </geometry>
    </collision>
    <inertial>
      <origin rpy="0 0 0" xyz="0.0 0.0 0.0"/>
      <mass value="0.064"/>
      <inertia ixx="0.000214698666667" ixy="0.0" ixz="0.0" iyy="0.000214698666667" iyz="0.0" izz="2.73066666667e-06"/>
    </inertial>
  </link>
  <!-- //////////////////////foot//////////////////// -->
  <joint name="lf_foot_fixed" type="fixed">
    <origin rpy="0 0 0" xyz="0 0 -0.23039"/>
    <parent link="lf_kfe"/>
    <child link="lf_foot"/>
  </joint>
  <link name="lf_foot">
    <visual>
      <origin rpy="0 0 0" xyz="0 0.018 0.02"/>
      <geometry>
        <mesh filename="package://minicheetah_description/meshes/foot.STL" scale="1 1 1"/>
      </geometry>
      <material name="white_black"/>
    </visual>
    <collision>
      <origin rpy="0 0 0" xyz="0 0.0 0.025"/>
      <geometry>
        <!-- <mesh filename="package://minicheetah_description/meshes/foot.STL" scale="1 1 1"/> -->
        <sphere radius="0.025"/>
      </geometry>
    </collision>
    <inertial>
      <origin rpy="0 0 0" xyz="0.0 0.0 0"/>
      <mass value="0.15"/>
      <inertia ixx="4.2135e-05" ixy="0.0" ixz="0.0" iyy="4.2135e-05" iyz="0.0" izz="4.2135e-05"/>
    </inertial>
  </link>

  <!-- //////////////////////haa//////////////////// -->
  <joint name="rh_haa_joint" type="revolute">
    <!-- <joint name="${name}_haa_joint" type="continuous"> -->
    <origin rpy="0 0 0" xyz="-0.196 -0.049664 0"/>
    <parent link="trunk"/>
    <child link="rh_haa"/>
    <axis xyz="1 0 0"/>
    <dynamics damping="0" rfiction="0"/>
    <limit effort="20" lower="-1.0471975512" upper="0.872664625997" velocity="10.6"/>
  </joint>
  <link name="rh_haa">
    <visual>
      <origin rpy="0 0 0" xyz="0 0 0"/>
      <geometry>
        <mesh filename="package://minicheetah_description/meshes/hip.STL" scale="1 1 1"/>
      </geometry>
      <material name="gold"/>
    </visual>
    <collision>
      <!-- <origin rpy="${PI/2.0} 0 0" xyz="0 0 0"/> -->
      <!-- <xacro:if value="${(mirhor_dae == True) and (rfont_hind_dae == True)}">
                    <origin rpy="0 0 0" xyz="0 0 0"/>
                </xacro:if>
                <xacro:if value="${(mirhor_dae == False) and (rfont_hind_dae == True)}">
                    <origin rpy="${PI} 0 0" xyz="0 0 0"/>
                </xacro:if>
                <xacro:if value="${(mirhor_dae == True) and (rfont_hind_dae == False)}">
                    <origin rpy="0 ${PI} 0" xyz="0 0 0"/>
                </xacro:if>
                <xacro:if value="${(mirhor_dae == False) and (rfont_hind_dae == False)}">
                    <origin rpy="${PI} ${PI} 0" xyz="0 0 0"/>
                </xacro:if> -->
      <geometry>
        <!-- <mesh filename="package://minicheetah_description/meshes/hip.STL" scale="1 1 1"/> -->
        <box size="0.09 0.08 0.093"/>
      </geometry>
    </collision>
    <inertial>
      <origin rpy="0 0 0" xyz="0.0 0.036 0.0"/>
      <mass value="0.57"/>
      <inertia ixx="0.0007148275" ixy="0.0" ixz="0.0" iyy="0.0007955775" iyz="0.0" izz="0.00068875"/>
    </inertial>
  </link>
  <!-- //////////////////////hfe//////////////////// -->
  <joint name="rh_hfe_joint" type="revolute">
    <!-- <joint name="${name}_hfe_joint" type="continuous"> -->
    <origin rpy="0 0 0" xyz="0 -0.077476 0"/>
    <parent link="rh_haa"/>
    <child link="rh_hfe"/>
    <axis xyz="0 1 0"/>
    <dynamics damping="0" rfiction="0"/>
    <limit effort="20" lower="-0.523598775598" upper="3.92699081699" velocity="10.6"/>
  </joint>
  <link name="rh_hfe">
    <visual>
      <origin rpy="0 0 0" xyz="0 0 0"/>
      <geometry>
        <mesh filename="package://minicheetah_description/meshes/thigh.STL" scale="1 1 1"/>
      </geometry>
      <material name="white_blue"/>
    </visual>
    <collision>
      <!-- <xacro:if value="${mirhor_dae == True}">
                    <origin rpy="0 0 0" xyz="0 0 0"/>
                </xacro:if>
                <xacro:if value="${mirhor_dae == False}">
                    <origin rpy="${PI} ${PI} 0" xyz="0 0 0"/>
                </xacro:if> -->
      <origin rpy="0 0 0" xyz="0 0 -0.11"/>
      <geometry>
        <box size="0.043 0.034 0.22"/>
        <!-- <mesh filename="package://minicheetah_description/meshes/thigh.STL" scale="1 1 1"/> -->
      </geometry>
      <material name="white_blue"/>
    </collision>
    <inertial>
      <origin rpy="0 0 0" xyz="0.0 0.016 -0.11"/>
      <mass value="0.634"/>
      <inertia ixx="0.00261820866667" ixy="0.0" ixz="0.0" iyy="0.00265482216667" iyz="0.0" izz="0.000158764166667"/>
    </inertial>
  </link>
  <!-- //////////////////////kfe//////////////////// -->
  <joint name="rh_kfe_joint" type="revolute">
    <!-- <joint name="${name}_kfe_joint" type="continuous"> -->
    <origin rpy="0 0 0" xyz="0 0 -0.2115"/>
    <parent link="rh_hfe"/>
    <child link="rh_kfe"/>
    <axis xyz="0 1 0"/>
    <dynamics damping="0" rfiction="0"/>
    <!-- <limit effort="${kfe_torque_max}" velocity="${kfe_velocity_max}" lower="${kfe_min*PI/180.0}" upper="${kfe_max*PI/180.0}"/> -->
    <limit effort="20" lower="-3.14159265359" upper="3.14159265359" velocity="10.6"/>
  </joint>
  <link name="rh_kfe">
    <visual>
      <origin rpy="0 0 0" xyz="0.0 0.009 0.0"/>
      <geometry>
        <mesh filename="package://minicheetah_description/meshes/calf.STL" scale="1 1 1"/>
      </geometry>
      <material name="white_blue"/>
    </visual>
    <collision>
      <origin rpy="0 0 0" xyz="0.0 0.0 -0.1"/>
      <geometry>
        <box size="0.016 0.016 0.2"/>
        <!-- <mesh filename="package://minicheetah_description/meshes/calf.STL" scale="1 1 1"/> -->
      </geometry>
    </collision>
    <inertial>
      <origin rpy="0 0 0" xyz="0.0 0.0 0.0"/>
      <mass value="0.064"/>
      <inertia ixx="0.000214698666667" ixy="0.0" ixz="0.0" iyy="0.000214698666667" iyz="0.0" izz="2.73066666667e-06"/>
    </inertial>
  </link>
  <!-- //////////////////////foot//////////////////// -->
  <joint name="rh_foot_fixed" type="fixed">
    <origin rpy="0 0 0" xyz="0 0 -0.23039"/>
    <parent link="rh_kfe"/>
    <child link="rh_foot"/>
  </joint>
  <link name="rh_foot">
    <visual>
      <origin rpy="0 0 0" xyz="0 0.018 0.02"/>
      <geometry>
        <mesh filename="package://minicheetah_description/meshes/foot.STL" scale="1 1 1"/>
      </geometry>
      <material name="white_black"/>
    </visual>
    <collision>
      <origin rpy="0 0 0" xyz="0 0.0 0.025"/>
      <geometry>
        <!-- <mesh filename="package://minicheetah_description/meshes/foot.STL" scale="1 1 1"/> -->
        <sphere radius="0.025"/>
      </geometry>
    </collision>
    <inertial>
      <origin rpy="0 0 0" xyz="0.0 0.0 0"/>
      <mass value="0.15"/>
      <inertia ixx="4.2135e-05" ixy="0.0" ixz="0.0" iyy="4.2135e-05" iyz="0.0" izz="4.2135e-05"/>
    </inertial>
  </link>

  <!-- //////////////////////haa//////////////////// -->
  <joint name="rf_haa_joint" type="revolute">
    <!-- <joint name="${name}_haa_joint" type="continuous"> -->
    <origin rpy="0 0 0" xyz="0.196 -0.049664 0"/>
    <parent link="trunk"/>
    <child link="rf_haa"/>
    <axis xyz="1 0 0"/>
    <dynamics damping="0" rfiction="0"/>
    <limit effort="20" lower="-1.0471975512" upper="0.872664625997" velocity="10.6"/>
  </joint>
  <link name="rf_haa">
    <visual>
      <origin rpy="0 3.14159265359 0" xyz="0 0 0"/>
      <geometry>
        <mesh filename="package://minicheetah_description/meshes/hip.STL" scale="1 1 1"/>
      </geometry>
      <material name="gold"/>
    </visual>
    <collision>
      <!-- <origin rpy="${PI/2.0} 0 0" xyz="0 0 0"/> -->
      <!-- <xacro:if value="${(mirhor_dae == True) and (rfont_hind_dae == True)}">
                    <origin rpy="0 0 0" xyz="0 0 0"/>
                </xacro:if>
                <xacro:if value="${(mirhor_dae == False) and (rfont_hind_dae == True)}">
                    <origin rpy="${PI} 0 0" xyz="0 0 0"/>
                </xacro:if>
                <xacro:if value="${(mirhor_dae == True) and (rfont_hind_dae == False)}">
                    <origin rpy="0 ${PI} 0" xyz="0 0 0"/>
                </xacro:if>
                <xacro:if value="${(mirhor_dae == False) and (rfont_hind_dae == False)}">
                    <origin rpy="${PI} ${PI} 0" xyz="0 0 0"/>
                </xacro:if> -->
      <geometry>
        <!-- <mesh filename="package://minicheetah_description/meshes/hip.STL" scale="1 1 1"/> -->
        <box size="0.09 0.08 0.093"/>
      </geometry>
    </collision>
    <inertial>
      <origin rpy="0 0 0" xyz="-0.0 0.036 0.0"/>
      <mass value="0.57"/>
      <inertia ixx="0.0007148275" ixy="0.0" ixz="0.0" iyy="0.0007955775" iyz="0.0" izz="0.00068875"/>
    </inertial>
  </link>
  <!-- //////////////////////hfe//////////////////// -->
  <joint name="rf_hfe_joint" type="revolute">
    <!-- <joint name="${name}_hfe_joint" type="continuous"> -->
    <origin rpy="0 0 0" xyz="0 -0.077476 0"/>
    <parent link="rf_haa"/>
    <child link="rf_hfe"/>
    <axis xyz="0 1 0"/>
    <dynamics damping="0" rfiction="0"/>
    <limit effort="20" lower="-0.523598775598" upper="3.92699081699" velocity="10.6"/>
  </joint>
  <link name="rf_hfe">
    <visual>
      <origin rpy="0 0 0" xyz="0 0 0"/>
      <geometry>
        <mesh filename="package://minicheetah_description/meshes/thigh.STL" scale="1 1 1"/>
      </geometry>
      <material name="white_blue"/>
    </visual>
    <collision>
      <!-- <xacro:if value="${mirhor_dae == True}">
                    <origin rpy="0 0 0" xyz="0 0 0"/>
                </xacro:if>
                <xacro:if value="${mirhor_dae == False}">
                    <origin rpy="${PI} ${PI} 0" xyz="0 0 0"/>
                </xacro:if> -->
      <origin rpy="0 0 0" xyz="0 0 -0.11"/>
      <geometry>
        <box size="0.043 0.034 0.22"/>
        <!-- <mesh filename="package://minicheetah_description/meshes/thigh.STL" scale="1 1 1"/> -->
      </geometry>
      <material name="white_blue"/>
    </collision>
    <inertial>
      <origin rpy="0 0 0" xyz="0.0 0.016 -0.11"/>
      <mass value="0.634"/>
      <inertia ixx="0.00261820866667" ixy="0.0" ixz="0.0" iyy="0.00265482216667" iyz="0.0" izz="0.000158764166667"/>
    </inertial>
  </link>
  <!-- //////////////////////kfe//////////////////// -->
  <joint name="rf_kfe_joint" type="revolute">
    <!-- <joint name="${name}_kfe_joint" type="continuous"> -->
    <origin rpy="0 0 0" xyz="0 0 -0.2115"/>
    <parent link="rf_hfe"/>
    <child link="rf_kfe"/>
    <axis xyz="0 1 0"/>
    <dynamics damping="0" rfiction="0"/>
    <!-- <limit effort="${kfe_torque_max}" velocity="${kfe_velocity_max}" lower="${kfe_min*PI/180.0}" upper="${kfe_max*PI/180.0}"/> -->
    <limit effort="20" lower="-3.14159265359" upper="3.14159265359" velocity="10.6"/>
  </joint>
  <link name="rf_kfe">
    <visual>
      <origin rpy="0 0 0" xyz="0.0 0.009 0.0"/>
      <geometry>
        <mesh filename="package://minicheetah_description/meshes/calf.STL" scale="1 1 1"/>
      </geometry>
      <material name="white_blue"/>
    </visual>
    <collision>
      <origin rpy="0 0 0" xyz="0.0 0.0 -0.1"/>
      <geometry>
        <box size="0.016 0.016 0.2"/>
        <!-- <mesh filename="package://minicheetah_description/meshes/calf.STL" scale="1 1 1"/> -->
      </geometry>
    </collision>
    <inertial>
      <origin rpy="0 0 0" xyz="0.0 0.0 0.0"/>
      <mass value="0.064"/>
      <inertia ixx="0.000214698666667" ixy="0.0" ixz="0.0" iyy="0.000214698666667" iyz="0.0" izz="2.73066666667e-06"/>
    </inertial>
  </link>

  <!-- //////////////////////foot//////////////////// -->
  <joint name="rf_foot_fixed" type="fixed">
    <origin rpy="0 0 0" xyz="0 0 -0.23039"/>
    <parent link="rf_kfe"/>
    <child link="rf_foot"/>
  </joint>
  <link name="rf_foot">
    <visual>
      <origin rpy="0 0 0" xyz="0 0.018 0.02"/>
      <geometry>
        <mesh filename="package://minicheetah_description/meshes/foot.STL" scale="1 1 1"/>
      </geometry>
      <material name="white_black"/>
    </visual>
    <collision>
      <origin rpy="0 0 0" xyz="0 0.0 0.025"/>
      <geometry>
        <!-- <mesh filename="package://minicheetah_description/meshes/foot.STL" scale="1 1 1"/> -->
        <sphere radius="0.025"/>
      </geometry>
    </collision>
    <inertial>
      <origin rpy="0 0 0" xyz="0.0 0.0 0"/>
      <mass value="0.15"/>
      <inertia ixx="4.2135e-05" ixy="0.0" ixz="0.0" iyy="4.2135e-05" iyz="0.0" izz="4.2135e-05"/>
    </inertial>
  </link>

  <link name="imu_link">
    <inertial>
      <mass value="0.001"/>
      <origin rpy="0 0 0" xyz="0 0 0"/>
      <inertia ixx="1e-09" ixy="0.0" ixz="0.0" iyy="1e-09" iyz="0.0" izz="1e-09"/>
    </inertial>
  </link>
  <joint name="imu_joint" type="fixed">
    <parent link="trunk"/>
    <child link="imu_link"/>
  </joint>

  <!-- Extensions -->
  <xacro:leg_transmission prefix="rf"/>
  <xacro:leg_gazebo prefix="rf" robot_name="$(arg robot_name)" load_force_sensors="$(arg load_force_sensors)"/>
  <xacro:leg_transmission prefix="lf"/>
  <xacro:leg_gazebo prefix="lf" robot_name="$(arg robot_name)" load_force_sensors="$(arg load_force_sensors)"/>
  <xacro:leg_transmission prefix="rh"/>
  <xacro:leg_gazebo prefix="rh" robot_name="$(arg robot_name)" load_force_sensors="$(arg load_force_sensors)"/>
  <xacro:leg_transmission prefix="lh"/>
  <xacro:leg_gazebo prefix="lh" robot_name="$(arg robot_name)" load_force_sensors="$(arg load_force_sensors)"/>

</robot>

